Workbook

Sheet Executive Dashboard
A1: GULONG | CHANNEL REVENUE
A3: September 1–24, 2026 • Backend order-date cohorts • Week 4 covers 3 days • Values exclude VAT
A6: ALL-ORDER NET SALES | D6: FULFILLED NET REVENUE | G6: OPEN ORDER NET VALUE | J6: CANCELLED NET VALUE
A7: 4799816.2 | D7: 2091465.3 | G7: 1332416.8 | J7: 1293777
A43: ANALYST FINDINGS & NEXT ACTIONS
A45: Direct & Organic contributes 62.5% of fulfilled net revenue (₱1,307,529).
A47: Cancelled orders represent ₱1,293,777, or 27.0% of September order value. Review cancellation reasons before increasing acquisition spend.
A49: Open orders hold ₱1,332,417. Prioritize payment and fulfillment follow-up; this value is not a revenue forecast.
A51: Week 4 averages ₱169,322 per day versus ₱196,039 in Week 3 (-13.6%). Three-day coverage and weekday mix limit comparison.
A53: Week 4 has no fulfilled revenue in this snapshot. These recent order cohorts have had less time to fulfill; this is not evidence of zero eventual sales.
A55: 8 fulfilled orders are partially paid. Fulfilled revenue uses full order value and is not cash collected.
A57: Backend customer type is an operational classification (Website/Fb/Chatbot), not new versus returning customer and not the analytics acquisition channel.
A59: No advertising spend, clicks or session denominators were supplied. ROAS, CAC and visitor-to-order conversion cannot be calculated from these exports.

Sheet Source Data
A1: Channel | B1: Session campaign | C1: Order ID | D1: Order date | E1: Week | F1: Scope | G1: Customer type | H1: Customer source | I1: Order status | J1: Payment status | K1: Net sales | L1: Fulfilled net revenue | M1: Gross order value | N1: Fulfilled flag | O1: Cancelled flag | P1: Open net value | Q1: Cancelled net value | R1: Return refund net value | S1: Purchase events | T1: Quantity | U1: Brand | V1: SKU | W1: Page path + query string | X1: Source file | Y1: Source CSV row | Z1: Backend loaded at | AA1: Backend updated at | AB1: Test order
A2: Google Ads | B2: All Brand - PMax PH | C2: 39773 | D2: 46286.792 | E2: Week 3 | F2: Included | G2: Website | I2: New | J2: Unpaid | K2: 8473.13 | L2: 0 | M2: 9489.9 | N2: 0 | O2: 0 | P2: 8473.13 | Q2: 0 | R2: 0 | S2: 4 | T2: 2 | U2: YOKOHAMA | V2: YOKOHAMA 185/65/R14 BLUEARTH ES32 86H | W2: /complete-order?requestid=Mzk3NzM%3D | X2: revenue_match/google_cpc.csv | Y2: 2 | Z2: 2026-09-25 02:00:22 | AA2: 2026-09-22T10:55:00 | AB2: false
A3: Google Ads | B3: BFG Advantage Touring – PMax PH | C3: 39143 | D3: 46270.549 | E3: Week 1 | F3: Included | G3: Website | I3: Fulfilled | J3: Fully Paid | K3: 37973.21 | L3: 37973.21 | M3: 42530 | N3: 1 | O3: 0 | P3: 0 | Q3: 0 | R3: 0 | S3: 2 | T3: 4 | U3: MICHELIN | V3: MICHELIN 265/65/R17 PRIMACY SUV+ 112H | W3: /complete-order?requestid=MzkxNDM%3D | X3: revenue_match/google_cpc.csv | Y3: 3 | Z3: 2026-09-25 02:00:22 | AA3: 2026-09-10T15:28:00 | AB3: false
A4: Google Ads | B4: MICHELIN - PMAX (Traffic) | C4: 39395 | D4: 46276.733 | E4: Week 2 | F4: Included | G4: Website | I4: Fulfilled | J4: Fully Paid | K4: 7095.27 | L4: 7095.27 | M4: 7946.7 | N4: 1 | O4: 0 | P4: 0 | Q4: 0 | R4: 0 | S4: 2 | T4: 3 | U4: ARIVO | V4: ARIVO 185/55/R15 PREMIO COMFORT 6 | W4: /complete-order?requestid=MzkzOTU%3D | X4: revenue_match/google_cpc.csv | Y4: 4 | Z4: 2026-09-25 02:00:22 | AA4: 2026-09-21T14:40:00 | AB4: false
A5: Google Ads | B5: Michelin - PMax PH | C5: 39497 | D5: 46279.678 | E5: Week 2 | F5: Included | G5: Website | H5: CALL | I5: Fulfilled | J5: Fully Paid | K5: 37191.96 | L5: 37191.96 | M5: 41655 | N5: 1 | O5: 0 | P5: 0 | Q5: 0 | R5: 0 | S5: 2 | T5: 4 | U5: MICHELIN | V5: MICHELIN 235/50/R18 PRIMACY 5 97W | W5: /complete-order?requestid=Mzk0OTc= | X5: revenue_match/google_cpc.csv | Y5: 5 | Z5: 2026-09-25 02:00:22 | AA5: 2026-09-22T11:50:00 | AB5: false
A6: Google Ads | B6: Michelin - PMax PH | C6: 39507 | D6: 46279.738 | E6: Week 2 | F6: Included | G6: Website | H6: Website | I6: Pending | J6: Partial Payment | K6: 26661.61 | L6: 0 | M6: 29861 | N6: 0 | O6: 0 | P6: 26661.61 | Q6: 0 | R6: 0 | S6: 2 | T6: 4 | U6: KINTO | V6: KINTO 285/40/ZR18 X-68+ 101W | W6: /complete-order?requestid=Mzk1MDc%3D | X6: revenue_match/google_cpc.csv | Y6: 6 | Z6: 2026-09-25 02:00:22 | AA6: 2026-09-17T11:10:00 | AB6: false
A7: Google Ads | B7: BFG Advantage Touring – PMax PH | C7: 39542 | D7: 46280.605 | E7: Week 3 | F7: Included | G7: Website | H7: Website | I7: Fulfilled | J7: Fully Paid | K7: 11506.7 | L7: 11506.7 | M7: 12887.5 | N7: 1 | O7: 0 | P7: 0 | Q7: 0 | R7: 0 | S7: 2 | T7: 5 | U7: WESTLAKE | V7: WESTLAKE 185/70/R14 RP36 | W7: /complete-order?requestid=Mzk1NDI%3D | X7: revenue_match/google_cpc.csv | Y7: 7 | Z7: 2026-09-25 02:00:22 | AA7: 2026-09-24T15:02:00 | AB7: false
A8: Google Ads | B8: All Brand - PMax PH | C8: 39568 | D8: 46281.465 | E8: Week 3 | F8: Included | G8: Website | I8: New | J8: Unpaid | K8: 15083.75 | L8: 0 | M8: 16893.8 | N8: 0 | O8: 0 | P8: 15083.75 | Q8: 0 | R8: 0 | S8: 2 | T8: 4 | U8: BFGOODRICH | V8: BFGOODRICH 195/50/R16 ADVANTAGE TOURING 88V | W8: /complete-order?requestid=Mzk1Njg= | X8: revenue_match/google_cpc.csv | Y8: 8 | Z8: 2026-09-25 02:00:22 | AA8: 2026-09-16T11:15:00 | AB8: false
A9: Google Ads | B9: SRC | All Brands | PH | C9: 39570 | D9: 46281.465 | E9: Week 3 | F9: Included | G9: Website | H9: Website | I9: New | J9: Unpaid | K9: 151683.75 | L9: 0 | M9: 169885.8 | N9: 0 | O9: 0 | P9: 151683.75 | Q9: 0 | R9: 0 | S9: 2 | T9: 12 | U9: TOYO | V9: TOYO 235/60/R18 OPAT3 107H | W9: /complete-order?requestid=Mzk1NzA= | X9: revenue_match/google_cpc.csv | Y9: 9 | Z9: 2026-09-25 02:00:22 | AA9: 2026-09-16T11:25:00 | AB9: false
A10: Google Ads | B10: Michelin - PMax PH | C10: 39581 | D10: 46281.585 | E10: Week 3 | F10: Included | G10: Website | I10: New | J10: Unpaid | K10: 45707.95 | L10: 0 | M10: 51192.9 | N10: 0 | O10: 0 | P10: 45707.95 | Q10: 0 | R10: 0 | S10: 2 | T10: 2 | U10: TOYO | V10: TOYO 275/45/R21 PROXES SPORT PXSP2 110Y | W10: /complete-order?requestid=Mzk1ODE= | X10: revenue_match/google_cpc.csv | Y10: 10 | Z10: 2026-09-25 02:00:22 | AA10: 2026-09-17T10:31:00 | AB10: false
A11: Google Ads | B11: Michelin - PMax PH | C11: 39583 | D11: 46281.593 | E11: Week 3 | F11: Included | G11: Website | I11: New | J11: Unpaid | K11: 45707.95 | L11: 0 | M11: 51192.9 | N11: 0 | O11: 0 | P11: 45707.95 | Q11: 0 | R11: 0 | S11: 2 | T11: 2 | U11: TOYO | V11: TOYO 275/45/R21 PROXES SPORT PXSP2 110Y | W11: /complete-order?requestid=Mzk1ODM= | X11: revenue_match/google_cpc.csv | Y11: 11 | Z11: 2026-09-25 02:00:22 | AA11: 2026-09-17T10:31:00 | AB11: false
A12: Google Ads | B12: All Brand - PMax PH | C12: 39586 | D12: 46281.64 | E12: Week 3 | F12: Included | G12: Website | H12: CALL | I12: Fulfilled | J12: Fully Paid | K12: 42857.14 | L12: 42857.14 | M12: 48000 | N12: 1 | O12: 0 | P12: 0 | Q12: 0 | R12: 0 | S12: 2 | T12: 4 | U12: MICHELIN | V12: MICHELIN 255/45/R20 PILOT SPORT EV 105W | W12: /complete-order?requestid=Mzk1ODY= | X12: revenue_match/google_cpc.csv | Y12: 12 | Z12: 2026-09-25 02:00:22 | AA12: 2026-09-22T15:56:00 | AB12: false
A13: Google Ads | B13: BFG Advantage Touring – PMax PH | C13: 39603 | D13: 46282.358 | E13: Week 3 | F13: Included | G13: Website | I13: New | J13: Unpaid | K13: 29117.32 | L13: 0 | M13: 32611.4 | N13: 0 | O13: 0 | P13: 29117.32 | Q13: 0 | R13: 0 | S13: 2 | T13: 8 | U13: HANKOOK | V13: HANKOOK 205/55/R16 VENTUS PRIME 4 91W | W13: /complete-order?requestid=Mzk2MDM= | X13: revenue_match/google_cpc.csv | Y13: 13 | Z13: 2026-09-25 02:00:22 | AA13: 2026-09-17T10:48:00 | AB13: false
A14: Google Ads | B14: Gulongph Branding - PMax | C14: 39608 | D14: 46282.418 | E14: Week 3 | F14: Included | G14: Website | H14: Website | I14: Fulfilled | J14: Fully Paid | K14: 4941.16 | L14: 4941.16 | M14: 5534.1 | N14: 1 | O14: 0 | P14: 0 | Q14: 0 | R14: 0 | S14: 2 | T14: 2 | U14: ARIVO | V14: ARIVO 185/60/R15 PREMIO COMFORT 6 88H | W14: /complete-order?requestid=Mzk2MDg%3D | X14: revenue_match/google_cpc.csv | Y14: 14 | Z14: 2026-09-25 02:00:22 | AA14: 2026-09-21T13:29:00 | AB14: false
A15: Google Ads | B15: BFG Advantage Touring – PMax PH | C15: 39623 | D15: 46282.468 | E15: Week 3 | F15: Included | G15: Website | H15: CALL | I15: Pending | J15: Partial Payment | K15: 30008.04 | L15: 0 | M15: 33609 | N15: 0 | O15: 0 | P15: 30008.04 | Q15: 0 | R15: 0 | S15: 2 | T15: 8 | U15: HANKOOK | V15: HANKOOK 205/55/R16 VENTUS PRIME 4 91W | W15: /complete-order?requestid=Mzk2MjM= | X15: revenue_match/google_cpc.csv | Y15: 15 | Z15: 2026-09-25 02:00:22 | AA15: 2026-09-24T15:39:00 | AB15: false
A16: Google Ads | B16: BFG Advantage Touring – PMax PH | C16: 39665 | D16: 46283.524 | E16: Week 3 | F16: Included | G16: Website | H16: Website | I16: Fulfilled | J16: Fully Paid | K16: 6785.71 | L16: 6785.71 | M16: 7600 | N16: 1 | O16: 0 | P16: 0 | Q16: 0 | R16: 0 | S16: 2 | T16: 2 | U16: BFGOODRICH | V16: BFGOODRICH 185/55/R15 ADVANTAGE TOURING 86V | W16: /complete-order?requestid=Mzk2NjU%3D | X16: revenue_match/google_cpc.csv | Y16: 16 | Z16: 2026-09-25 02:00:22 | AA16: 2026-09-24T14:23:00 | AB16: false
A17: Google Ads | B17: BFG Advantage Touring – PMax PH | C17: 39677 | D17: 46283.717 | E17: Week 3 | F17: Included | G17: Website | H17: Website | I17: New | J17: Unpaid | K17: 4808.04 | L17: 0 | M17: 5385 | N17: 0 | O17: 0 | P17: 4808.04 | Q17: 0 | R17: 0 | S17: 2 | T17: 1 | U17: BFGOODRICH | V17: BFGOODRICH 215/45/R17 ADVANTAGE TOURING 91V | W17: /complete-order?requestid=Mzk2Nzc= | X17: revenue_match/google_cpc.csv | Y17: 17 | Z17: 2026-09-25 02:00:22 | AA17: 2026-09-21T15:58:00 | AB17: false
A18: Google Ads | B18: BFG Advantage Touring – PMax PH | C18: 39691 | D18: 46284.056 | E18: Week 3 | F18: Included | G18: Website | H18: Website | I18: Processing | J18: Fully Paid | K18: 39419.64 | L18: 0 | M18: 44150 | N18: 0 | O18: 0 | P18: 39419.64 | Q18: 0 | R18: 0 | S18: 2 | T18: 4 | U18: MICHELIN | V18: MICHELIN 255/40/ZR18 PILOT SPORT 5 99Y XL TL | W18: /complete-order?requestid=Mzk2OTE%3D | X18: revenue_match/google_cpc.csv | Y18: 18 | Z18: 2026-09-25 02:00:22 | AA18: 2026-09-23T15:18:00 | AB18: false
A19: Google Ads | B19: All Brand - PMax PH | C19: 39692 | D19: 46284.353 | E19: Week 3 | F19: Included | G19: Website | I19: Fulfilled | J19: Partial Payment | K19: 14979.64 | L19: 14979.64 | M19: 16777.2 | N19: 1 | O19: 0 | P19: 0 | Q19: 0 | R19: 0 | S19: 2 | T19: 4 | U19: BRIDGESTONE | V19: BRIDGESTONE 175/65/R14 ECOPIA EP150 82H | W19: /complete-order?requestid=Mzk2OTI%3D | X19: revenue_match/google_cpc.csv | Y19: 19 | Z19: 2026-09-25 02:00:22 | AA19: 2026-09-24T09:59:00 | AB19: false
A20: Google Ads | B20: Michelin - PMax PH | C20: 39705 | D20: 46284.667 | E20: Week 3 | F20: Included | G20: Website | H20: Website | I20: Cancelled | J20: Fully Paid | K20: 10851.25 | L20: 0 | M20: 12153.4 | N20: 0 | O20: 1 | P20: 0 | Q20: 10851.25 | R20: 0 | S20: 2 | T20: 4 | U20: BFGOODRICH | V20: BFGOODRICH 175/65/R14 ADVANTAGE TOURING 82H | W20: /complete-order?requestid=Mzk3MDU%3D | X20: revenue_match/google_cpc.csv | Y20: 20 | Z20: 2026-09-25 02:00:22 | AA20: 2026-09-22T14:02:00 | AB20: false
A21: Google Ads | B21: (cross-network) | C21: 39736 | D21: 46285.798 | E21: Week 3 | F21: Included | G21: Website | I21: Fulfilled | J21: Fully Paid | K21: 8613.66 | L21: 8613.66 | M21: 9647.3 | N21: 1 | O21: 0 | P21: 0 | Q21: 0 | R21: 0 | S21: 2 | T21: 2 | U21: YOKOHAMA | V21: YOKOHAMA 185/60/R15 BLUEARTH ES32 84H | W21: /complete-order?requestid=Mzk3MzY%3D | X21: revenue_match/google_cpc.csv | Y21: 21 | Z21: 2026-09-25 02:00:22 | AA21: 2026-09-24T14:48:00 | AB21: false
A22: Google Ads | B22: Michelin - PMax PH | C22: 39738 | D22: 46285.822 | E22: Week 3 | F22: Included | G22: Website | I22: For Return | J22: Partial Payment | K22: 10940.54 | L22: 0 | M22: 12253.4 | N22: 0 | O22: 0 | P22: 0 | Q22: 0 | R22: 10940.54 | S22: 2 | T22: 4 | U22: BFGOODRICH | V22: BFGOODRICH 175/65/R14 ADVANTAGE TOURING 82H | W22: /complete-order?requestid=Mzk3Mzg%3D | X22: revenue_match/google_cpc.csv | Y22: 22 | Z22: 2026-09-25 02:00:22 | AA22: 2026-09-23T10:01:00 | AB22: false
A23: Google Ads | B23: All Brand - PMax PH | C23: 39816 | D23: 46287.829 | E23: Week 4 | F23: Included | G23: Website | H23: Website | I23: Processing | J23: Fully Paid | K23: 19370.54 | L23: 0 | M23: 21695 | N23: 0 | O23: 0 | P23: 19370.54 | Q23: 0 | R23: 0 | S23: 2 | T23: 4 | U23: MICHELIN | V23: MICHELIN 185/55/R15 ENERGY XM2+ 86V | W23: /complete-order?requestid=Mzk4MTY%3D | X23: revenue_match/google_cpc.csv | Y23: 23 | Z23: 2026-09-25 02:00:22 | AA23: 2026-09-23T11:50:00 | AB23: false
A24: Google Ads | B24: Gulongph Branding - PMax | C24: 39835 | D24: 46288.509 | E24: Week 4 | F24: Included | G24: Website | I24: Pending | J24: Fully Paid | K24: 6370.54 | L24: 0 | M24: 7135 | N24: 0 | O24: 0 | P24: 6370.54 | Q24: 0 | R24: 0 | S24: 2 | T24: 1 | U24: YOKOHAMA | V24: YOKOHAMA 205/65/R16 BLUEARTH E70B 95H | W24: /complete-order?requestid=Mzk4MzU%3D | X24: revenue_match/google_cpc.csv | Y24: 24 | Z24: 2026-09-25 02:00:22 | AA24: 2026-09-23T12:15:00 | AB24: false
A25: Google Ads | B25: BFG Advantage Touring – PMax PH | C25: 39862 | D25: 46288.753 | E25: Week 4 | F25: Included | G25: Website | I25: Processing | J25: Fully Paid | K25: 26638.93 | L25: 0 | M25: 29835.6 | N25: 0 | O25: 0 | P25: 26638.93 | Q25: 0 | R25: 0 | S25: 2 | T25: 4 | U25: CST | V25: CST 265/60/R18 SAHARA AT 2 110T | W25: /complete-order?requestid=Mzk4NjI%3D | X25: revenue_match/google_cpc.csv | Y25: 25 | Z25: 2026-09-25 02:00:22 | AA25: 2026-09-24T12:11:00 | AB25: false
A26: Google Ads | B26: BFG Advantage Touring – PMax PH | C26: 39870 | D26: 46289.392 | E26: Week 4 | F26: Included | G26: Website | I26: Pending | J26: Partial Payment | K26: 11310.18 | L26: 0 | M26: 12667.4 | N26: 0 | O26: 0 | P26: 11310.18 | Q26: 0 | R26: 0 | S26: 2 | T26: 4 | U26: ARIVO | V26: ARIVO 205/65/R15 PREMIO COMFORT 6 94V | W26: /complete-order?requestid=Mzk4NzA= | X26: revenue_match/google_cpc.csv | Y26: 26 | Z26: 2026-09-25 02:00:22 | AA26: 2026-09-24T09:27:00 | AB26: false
A27: Google Ads | B27: Michelin - PMax PH | C27: 39877 | D27: 46289.408 | E27: Week 4 | F27: Included | G27: Website | I27: Cancelled | J27: Pending | K27: 21785.71 | L27: 0 | M27: 24400 | N27: 0 | O27: 1 | P27: 0 | Q27: 21785.71 | R27: 0 | S27: 2 | T27: 4 | U27: BFGOODRICH | V27: BFGOODRICH 225/55/R18 ADVANTAGE TOURING 98H | W27: /complete-order?requestid=Mzk4Nzc= | X27: revenue_match/google_cpc.csv | Y27: 27 | Z27: 2026-09-25 02:00:22 | AA27: 2026-09-24T10:30:00 | AB27: false
A28: Google Ads | B28: Michelin - PMax PH | C28: 39878 | D28: 46289.408 | E28: Week 4 | F28: Included | G28: Website | H28: Website | I28: Cancelled | J28: Pending | K28: 21785.71 | L28: 0 | M28: 24400 | N28: 0 | O28: 1 | P28: 0 | Q28: 21785.71 | R28: 0 | S28: 2 | T28: 4 | U28: BFGOODRICH | V28: BFGOODRICH 225/55/R18 ADVANTAGE TOURING 98H | W28: /complete-order?requestid=Mzk4Nzg= | X28: revenue_match/google_cpc.csv | Y28: 28 | Z28: 2026-09-25 02:00:22 | AA28: 2026-09-24T10:29:00 | AB28: false
A29: Google Ads | B29: BFG Advantage Touring – PMax PH | C29: 39895 | D29: 46289.543 | E29: Week 4 | F29: Included | G29: Website | I29: New | J29: Unpaid | K29: 10774.91 | L29: 0 | M29: 12067.9 | N29: 0 | O29: 0 | P29: 10774.91 | Q29: 0 | R29: 0 | S29: 2 | T29: 2 | U29: BFGOODRICH | V29: BFGOODRICH 225/50/R17 ADVANTAGE TOURING 98V | W29: /complete-order?requestid=Mzk4OTU= | X29: revenue_match/google_cpc.csv | Y29: 29 | Z29: 2026-09-25 02:00:22 | AA29: 2026-09-24T13:02:00 | AB29: false
A30: Google Ads | B30: Michelin - PMax PH | C30: 39898 | D30: 46289.612 | E30: Week 4 | F30: Included | G30: Website | H30: CHAT | I30: Processing | J30: Fully Paid | K30: 27812.14 | L30: 0 | M30: 31149.6 | N30: 0 | O30: 0 | P30: 27812.14 | Q30: 0 | R30: 0 | S30: 2 | T30: 4 | U30: YOKOHAMA | V30: YOKOHAMA 215/60/R17 GEOLANDAR CV G058 96H | W30: /complete-order?requestid=Mzk4OTg= | X30: revenue_match/google_cpc.csv | Y30: 30 | Z30: 2026-09-25 02:00:22 | AA30: 2026-09-24T14:46:00 | AB30: false
A31: Google Ads | B31: Michelin - PMax PH | C31: 39017 | D31: 46267.26 | E31: Week 1 | F31: Included | G31: Website | H31: Website | I31: Fulfilled | J31: Fully Paid | K31: 14073.04 | L31: 14073.04 | M31: 15761.8 | N31: 1 | O31: 0 | P31: 0 | Q31: 0 | R31: 0 | S31: 2 | T31: 4 | U31: BFGOODRICH | V31: BFGOODRICH 185/65/R15 ADVANTAGE TOURING 88H | W31: /complete-order?requestid=MzkwMTc%3D | X31: revenue_match/google_cpc.csv | Y31: 31 | Z31: 2026-09-25 02:00:22 | AA31: 2026-09-18T09:41:00 | AB31: false
A32: Google Ads | B32: Michelin - PMax PH | C32: 39032 | D32: 46267.513 | E32: Week 1 | F32: Included | G32: Website | H32: CALL | I32: Fulfilled | J32: Fully Paid | K32: 24990.18 | L32: 24990.18 | M32: 27989 | N32: 1 | O32: 0 | P32: 0 | Q32: 0 | R32: 0 | S32: 2 | T32: 4 | U32: YOKOHAMA | V32: YOKOHAMA 215/55/R16 BLUEARTH GT AE51 97W | W32: /complete-order?requestid=MzkwMzI%3D | X32: revenue_match/google_cpc.csv | Y32: 32 | Z32: 2026-09-25 02:00:22 | AA32: 2026-09-18T09:42:00 | AB32: false
A33: Google Ads | B33: All Brand - PMax PH | C33: 39034 | D33: 46267.556 | E33: Week 1 | F33: Included | G33: Website | I33: New | J33: Unpaid | K33: 19659.82 | L33: 0 | M33: 22019 | N33: 0 | O33: 0 | P33: 19659.82 | Q33: 0 | R33: 0 | S33: 2 | T33: 4 | U33: HANKOOK | V33: HANKOOK 205/55/R17 VENTUS PRIME 4 95V | W33: /complete-order?requestid=MzkwMzQ= | X33: revenue_match/google_cpc.csv | Y33: 33 | Z33: 2026-09-25 02:00:22 | AA33: 2026-09-02T14:15:00 | AB33: false
A34: Google Ads | B34: All Brand - PMax PH | C34: 39035 | D34: 46267.56 | E34: Week 1 | F34: Included | G34: Website | H34: Website | I34: New | J34: Unpaid | K34: 19659.82 | L34: 0 | M34: 22019 | N34: 0 | O34: 0 | P34: 19659.82 | Q34: 0 | R34: 0 | S34: 2 | T34: 4 | U34: HANKOOK | V34: HANKOOK 205/55/R17 VENTUS PRIME 4 95V | W34: /complete-order?requestid=MzkwMzU= | X34: revenue_match/google_cpc.csv | Y34: 34 | Z34: 2026-09-25 02:00:22 | AA34: 2026-09-02T14:16:00 | AB34: false
A35: Google Ads | B35: Michelin - PMax PH | C35: 39065 | D35: 46267.885 | E35: Week 1 | F35: Included | G35: Website | I35: Fulfilled | J35: Fully Paid | K35: 42234.11 | L35: 42234.11 | M35: 47302.2 | N35: 1 | O35: 0 | P35: 0 | Q35: 0 | R35: 0 | S35: 2 | T35: 4 | U35: DUNLOP | V35: DUNLOP 265/50/R20 GRANDTREK PT5 107V | W35: /complete-order?requestid=MzkwNjU%3D | X35: revenue_match/google_cpc.csv | Y35: 35 | Z35: 2026-09-25 02:00:22 | AA35: 2026-09-22T11:23:00 | AB35: false
A36: Google Ads | B36: Michelin - PMax PH | C36: 38959 | D36: 46265.788 | E36: Outside / unknown | F36: Outside period | G36: Website | H36: Website | I36: Fulfilled | J36: Fully Paid | K36: 27053.57 | L36: 27053.57 | M36: 30300 | N36: 1 | O36: 0 | P36: 0 | Q36: 0 | R36: 0 | S36: 2 | T36: 4 | U36: MICHELIN | V36: MICHELIN 195/60/R16 PRIMACY 5 93V | W36: /complete-order?requestid=Mzg5NTk= | X36: revenue_match/google_cpc.csv | Y36: 36 | Z36: 2026-09-25 02:00:22 | AA36: 2026-09-22T16:14:00 | AB36: false
A37: Google Ads | B37: Michelin - PMax PH | C37: 39158 | D37: 46271.674 | E37: Week 1 | F37: Included | G37: Website | H37: Website | I37: Fulfilled | J37: Fully Paid | K37: 4517.77 | L37: 4517.77 | M37: 5059.9 | N37: 1 | O37: 0 | P37: 0 | Q37: 0 | R37: 0 | S37: 2 | T37: 2 | U37: CST | V37: CST 155/80/R13 MARQUIS MR61 79T | W37: /complete-order?requestid=MzkxNTg%3D | X37: revenue_match/google_cpc.csv | Y37: 37 | Z37: 2026-09-25 02:00:22 | AA37: 2026-09-11T18:53:00 | AB37: false
A38: Google Ads | B38: Gulongph Branding - PMax | C38: 39164 | D38: 46271.9 | E38: Week 1 | F38: Included | G38: Website | I38: New | J38: Unpaid | K38: 45796.43 | L38: 0 | M38: 51292 | N38: 0 | O38: 0 | P38: 45796.43 | Q38: 0 | R38: 0 | S38: 2 | T38: 5 | U38: HANKOOK | V38: HANKOOK 265/50/R20 DYNAPRO AT2 XTREME RF12 111T | W38: /complete-order?requestid=MzkxNjQ%3D | X38: revenue_match/google_cpc.csv | Y38: 38 | Z38: 2026-09-25 02:00:22 | AA38: 2026-09-07T13:17:00 | AB38: false
A39: Google Ads | B39: Gulongph Branding - PMax | C39: 39166 | D39: 46271.905 | E39: Week 1 | F39: Included | G39: Website | I39: Fulfilled | J39: Fully Paid | K39: 45796.43 | L39: 45796.43 | M39: 51292 | N39: 1 | O39: 0 | P39: 0 | Q39: 0 | R39: 0 | S39: 2 | T39: 5 | U39: HANKOOK | V39: HANKOOK 265/50/R20 DYNAPRO AT2 XTREME RF12 111T | W39: /complete-order?requestid=MzkxNjY%3D | X39: revenue_match/google_cpc.csv | Y39: 39 | Z39: 2026-09-25 02:00:22 | AA39: 2026-09-10T15:23:00 | AB39: false
A40: Google Ads | B40: Michelin - PMax PH | C40: 39169 | D40: 46271.919 | E40: Week 1 | F40: Included | G40: Website | I40: Fulfilled | J40: Fully Paid | K40: 8129.46 | L40: 8129.46 | M40: 9105 | N40: 1 | O40: 0 | P40: 0 | Q40: 0 | R40: 0 | S40: 2 | T40: 2 | U40: ARIVO | V40: ARIVO 215/70/R16C TRANSITO ARZ 6-X | W40: /complete-order?requestid=MzkxNjk%3D | X40: revenue_match/google_cpc.csv | Y40: 40 | Z40: 2026-09-25 02:00:22 | AA40: 2026-09-10T15:22:00 | AB40: false
...

Sheet Original Google Ads
A1: Session campaign | B1: Page path + query string | C1: Ecommerce purchases
A2: All Brand - PMax PH | B2: /complete-order?requestid=Mzk3NzM%3D | C2: 4
A3: BFG Advantage Touring – PMax PH | B3: /complete-order?requestid=MzkxNDM%3D | C3: 2
A4: MICHELIN - PMAX (Traffic) | B4: /complete-order?requestid=MzkzOTU%3D | C4: 2
A5: Michelin - PMax PH | B5: /complete-order?requestid=Mzk0OTc= | C5: 2
A6: Michelin - PMax PH | B6: /complete-order?requestid=Mzk1MDc%3D | C6: 2
A7: BFG Advantage Touring – PMax PH | B7: /complete-order?requestid=Mzk1NDI%3D | C7: 2
A8: All Brand - PMax PH | B8: /complete-order?requestid=Mzk1Njg= | C8: 2
A9: SRC | All Brands | PH | B9: /complete-order?requestid=Mzk1NzA= | C9: 2
A10: Michelin - PMax PH | B10: /complete-order?requestid=Mzk1ODE= | C10: 2
A11: Michelin - PMax PH | B11: /complete-order?requestid=Mzk1ODM= | C11: 2
A12: All Brand - PMax PH | B12: /complete-order?requestid=Mzk1ODY= | C12: 2
... A69: All Brand - PMax PH | B69: /complete-order?requestid=MzkzOTc= | C69: 1

Sheet Original Direct Organic
A1: Session campaign | B1: Page path + query string | C1: Ecommerce purchases
A2: (direct) | B2: /complete-order?requestid=Mzk1OTI= | C2: 3
A3: (organic) | B3: /complete-order?requestid=MzkyMDA= | C3: 2
A4: (direct) | B4: /complete-order?requestid=MzkzOTA%3D | C4: 2
A5: (direct) | B5: /complete-order?requestid=Mzg5OTA= | C5: 2
A6: (direct) | B6: /complete-order?requestid=Mzg5OTY= | C6: 2
A7: (organic) | B7: /complete-order?requestid=Mzk0MDE%3D | C7: 2
A8: (organic) | B8: /complete-order?requestid=Mzk0MDQ= | C8: 2
A9: (direct) | B9: /complete-order?requestid=Mzk0MDY= | C9: 2
A10: (direct) | B10: /complete-order?requestid=Mzk0MDc= | C10: 2
A11: (organic) | B11: /complete-order?requestid=Mzk0MDk%3D | C11: 2
A12: (organic) | B12: /complete-order?requestid=Mzk0MTc= | C12: 2
... A172: (organic) | B172: /complete-order?requestid=MzkzODI= | C172: 1

Sheet Original Referral
A1: Session campaign | B1: Page path + query string | C1: Ecommerce purchases
A2: (referral) | B2: /complete-order?requestid=Mzk0NDg%3D | C2: 2
A3: (referral) | B3: /complete-order?requestid=Mzk0NjA= | C3: 2
A4: (referral) | B4: /complete-order?requestid=Mzk0ODU%3D | C4: 2
A5: (referral) | B5: /complete-order?requestid=Mzk0OTA%3D | C5: 2
A6: (referral) | B6: /complete-order?requestid=Mzk3MjM%3D | C6: 2
A7: (referral) | B7: /complete-order?requestid=MzkwNzU%3D | C7: 2
A8: (referral) | B8: /complete-order?requestid=MzkxMDE%3D | C8: 2
A9: (referral) | B9: /complete-order?requestid=MzkxMjU= | C9: 2
A10: (referral) | B10: /complete-order?requestid=MzkyOTM%3D | C10: 2
A11: (referral) | B11: /complete-order?requestid=MzkzNjQ%3D | C11: 2
A12: (referral) | B12: /complete-order?requestid=MzkzNjk= | C12: 2
... A29: (referral) | B29: /complete-order?requestid=MzkzOTI= | C29: 1

Sheet Backend Extract
A1: _ingest_loaded_at | B1: brand | C1: customer_source_raw | D1: customer_type_norm | E1: customer_type_raw | F1: date_updated | G1: gross_sales_amount | H1: is_excluded_test_order | I1: is_fulfilled_order | J1: is_fulfillment_success_order | K1: is_non_cancelled_order | L1: net_sales_amount | M1: order_date | N1: order_id | O1: order_status_raw | P1: payment_status_raw | Q1: quantity_int | R1: sku
A2: 2026-09-25 02:00:22 | B2: MICHELIN | C2: CALL | D2: fb | E2: Fb | F2: 2026-09-18T09:53:00 | G2: 60675 | H2: false | I2: true | J2: true | K2: true | L2: 54174.11 | M2: 2026-08-26T14:54:00 | N2: 38805 | O2: Fulfilled | P2: Fully Paid | Q2: 4 | R2: MICHELIN 225/45/ZR19 PILOT SPORT 5 96Y XL TL
A3: 2026-09-25 02:00:22 | B3: MICHELIN | C3: Website | D3: website | E3: Website | F3: 2026-09-22T16:14:00 | G3: 30300 | H3: false | I3: true | J3: true | K3: true | L3: 27053.57 | M3: 2026-08-31T18:55:00 | N3: 38959 | O3: Fulfilled | P3: Fully Paid | Q3: 4 | R3: MICHELIN 195/60/R16 PRIMACY 5 93V
A4: 2026-09-25 02:00:22 | B4: VREDESTEIN | C4: Website | D4: website | E4: Website | F4: 2026-09-07T15:52:00 | G4: 29175 | H4: false | I4: true | J4: true | K4: true | L4: 26049.11 | M4: 2026-09-01T10:13:00 | N4: 38967 | O4: Fulfilled | P4: Fully Paid | Q4: 4 | R4: VREDESTEIN 265/60/R18 PINZA AT 110H
A5: 2026-09-25 02:00:22 | B5: BFGOODRICH | D5: website | E5: Website | F5: 2026-09-18T09:38:00 | G5: 6945.6 | H5: false | I5: true | J5: true | K5: true | L5: 6201.43 | M5: 2026-09-01T10:39:00 | N5: 38969 | O5: Fulfilled | P5: Fully Paid | Q5: 2 | R5: BFGOODRICH 185/55/R16 ADVANTAGE TOURING 87H
A6: 2026-09-25 02:00:22 | B6: MICHELIN | C6: Website | D6: website | E6: Website | F6: 2026-09-18T09:42:00 | G6: 20190 | H6: false | I6: true | J6: true | K6: true | L6: 18026.79 | M6: 2026-09-01T10:49:00 | N6: 38970 | O6: Fulfilled | P6: Fully Paid | Q6: 4 | R6: MICHELIN 185/60/R14 ENERGY XM2+ 82H
A7: 2026-09-25 02:00:22 | B7: ARIVO | C7: Website | D7: website | E7: Website | F7: 2026-09-22T13:17:00 | G7: 10644.6 | H7: false | I7: true | J7: true | K7: true | L7: 9504.11 | M7: 2026-09-01T12:52:00 | N7: 38981 | O7: Fulfilled | P7: Fully Paid | Q7: 4 | R7: ARIVO 185/60/R15 PREMIO COMFORT 6 88H
A8: 2026-09-25 02:00:22 | B8: MICHELIN | C8: CALL | D8: website | E8: Website | F8: 2026-09-18T09:48:00 | G8: 64140 | H8: false | I8: true | J8: true | K8: true | L8: 57267.86 | M8: 2026-09-01T13:26:00 | N8: 38985 | O8: Fulfilled | P8: Fully Paid | Q8: 4 | R8: MICHELIN 275/60/R20 PRIMACY SUV+ 115H
A9: 2026-09-25 02:00:22 | B9: WESTLAKE | C9: CHAT | D9: fb | E9: Fb | F9: 2026-09-23T10:59:00 | G9: 4608.5 | H9: false | I9: true | J9: true | K9: true | L9: 4114.73 | M9: 2026-09-01T14:40:00 | N9: 38990 | O9: Fulfilled | P9: Fully Paid | Q9: 2 | R9: WESTLAKE 165/60/R14 RP36
A10: 2026-09-25 02:00:22 | B10: BRIDGESTONE | D10: website | E10: Website | F10: 2026-09-23T16:30:00 | G10: 4240 | H10: false | I10: false | J10: false | K10: false | L10: 3785.71 | M10: 2026-09-01T15:30:00 | N10: 38993 | O10: Cancelled | P10: Pending | Q10: 1 | R10: BRIDGESTONE 175/65/R14 ECOPIA EP150 82H
A11: 2026-09-25 02:00:22 | B11: WESTLAKE | C11: CHAT | D11: fb | E11: Fb | F11: 2026-09-22T11:57:00 | G11: 9333.2 | H11: false | I11: true | J11: true | K11: true | L11: 8333.21 | M11: 2026-09-01T17:12:00 | N11: 38996 | O11: Fulfilled | P11: Fully Paid | Q11: 4 | R11: WESTLAKE 165/65/R13 RP36
A12: 2026-09-25 02:00:22 | B12: BFGOODRICH | C12: Website | D12: website | E12: Website | F12: 2026-09-23T16:26:00 | G12: 14950 | H12: false | I12: false | J12: false | K12: false | L12: 13348.21 | M12: 2026-09-01T17:31:00 | N12: 38997 | O12: Cancelled | P12: Pending | Q12: 4 | R12: BFGOODRICH 185/55/R15 ADVANTAGE TOURING 86V
A13: 2026-09-25 02:00:22 | B13: ARIVO | D13: website | E13: Website | F13: 2026-09-10T16:35:00 | G13: 12201.8 | H13: false | I13: false | J13: false | K13: false | L13: 10894.46 | M13: 2026-09-01T20:10:00 | N13: 39004 | O13: Cancelled | P13: Pending | Q13: 4 | R13: ARIVO 195/50/R16 ULTRA ARZ5 84V
A14: 2026-09-25 02:00:22 | B14: ARIVO | D14: website | E14: Website | F14: 2026-09-18T09:40:00 | G14: 12451.8 | H14: false | I14: true | J14: true | K14: true | L14: 11117.68 | M14: 2026-09-01T20:13:00 | N14: 39005 | O14: Fulfilled | P14: Fully Paid | Q14: 4 | R14: ARIVO 195/50/R16 ULTRA ARZ5 84V
A15: 2026-09-25 02:00:22 | B15: WESTLAKE | C15: Website | D15: website | E15: Website | F15: 2026-09-23T16:26:00 | G15: 4631.2 | H15: false | I15: false | J15: false | K15: false | L15: 4135 | M15: 2026-09-01T20:27:00 | N15: 39006 | O15: Cancelled | P15: Pending | Q15: 2 | R15: WESTLAKE 185/70/R13 RP36
A16: 2026-09-25 02:00:22 | B16: CHENGSHAN | D16: website | E16: Website | F16: 2026-09-10T16:33:00 | G16: 4225.3 | H16: false | I16: false | J16: false | K16: false | L16: 3772.59 | M16: 2026-09-01T22:59:00 | N16: 39011 | O16: Cancelled | P16: Pending | Q16: 2 | R16: CHENGSHAN 175/70/R14 CSC-802 84H
A17: 2026-09-25 02:00:22 | B17: YOKOHAMA | C17: Website | D17: website | E17: Website | F17: 2026-09-23T16:26:00 | G17: 21434.8 | H17: false | I17: false | J17: false | K17: false | L17: 19138.21 | M17: 2026-09-01T23:19:00 | N17: 39012 | O17: Cancelled | P17: Pending | Q17: 4 | R17: YOKOHAMA 205/65/R15 BLUEARTH ES32 94H
A18: 2026-09-25 02:00:22 | B18: BFGOODRICH | C18: Website | D18: website | E18: Website | F18: 2026-09-14T09:54:00 | G18: 8598.9 | H18: false | I18: false | J18: false | K18: false | L18: 7677.59 | M18: 2026-09-01T23:36:00 | N18: 39014 | O18: Cancelled | P18: Fully Paid | Q18: 2 | R18: BFGOODRICH 205/65/R15 ADVANTAGE TOURING 99H
A19: 2026-09-25 02:00:22 | B19: ARIVO | C19: Website | D19: website | E19: Website | F19: 2026-09-23T16:26:00 | G19: 6730 | H19: false | I19: false | J19: false | K19: false | L19: 6008.93 | M19: 2026-09-02T01:19:00 | N19: 39015 | O19: Cancelled | P19: Pending | Q19: 2 | R19: ARIVO 205/50/R16 PREMIO SPORT 6 91W
A20: 2026-09-25 02:00:22 | B20: BFGOODRICH | C20: Website | D20: website | E20: Website | F20: 2026-09-18T09:41:00 | G20: 15761.8 | H20: false | I20: true | J20: true | K20: true | L20: 14073.04 | M20: 2026-09-02T06:14:00 | N20: 39017 | O20: Fulfilled | P20: Fully Paid | Q20: 4 | R20: BFGOODRICH 185/65/R15 ADVANTAGE TOURING 88H
A21: 2026-09-25 02:00:22 | B21: COMFORSER | D21: website | E21: Website | F21: 2026-09-23T16:25:00 | G21: 10501.4 | H21: false | I21: false | J21: false | K21: false | L21: 9376.25 | M21: 2026-09-02T07:05:00 | N21: 39018 | O21: Cancelled | P21: Pending | Q21: 4 | R21: COMFORSER 185/60/R15 CF510 84H
A22: 2026-09-25 02:00:22 | B22: BFGOODRICH | C22: Website | D22: website | E22: Website | F22: 2026-09-18T09:47:00 | G22: 12153.4 | H22: false | I22: true | J22: true | K22: true | L22: 10851.25 | M22: 2026-09-02T08:17:00 | N22: 39020 | O22: Fulfilled | P22: Fully Paid | Q22: 4 | R22: BFGOODRICH 175/65/R14 ADVANTAGE TOURING 82H
A23: 2026-09-25 02:00:22 | B23: WESTLAKE | C23: Website | D23: website | E23: Website | F23: 2026-09-22T16:15:00 | G23: 36221.2 | H23: false | I23: true | J23: true | K23: true | L23: 32340.36 | M23: 2026-09-02T09:38:00 | N23: 39023 | O23: Fulfilled | P23: Fully Paid | Q23: 4 | R23: WESTLAKE 305/35/R24 SA57
A24: 2026-09-25 02:00:22 | B24: LAUFENN | C24: CHAT | D24: website | E24: Website | F24: 2026-09-22T09:25:00 | G24: 6808.2 | H24: false | I24: true | J24: true | K24: true | L24: 6078.75 | M24: 2026-09-02T11:07:00 | N24: 39026 | O24: Fulfilled | P24: Fully Paid | Q24: 2 | R24: LAUFENN 195/60/R15 G FIT AS 88V
A25: 2026-09-25 02:00:22 | B25: YOKOHAMA | C25: CALL | D25: website | E25: Website | F25: 2026-09-18T09:42:00 | G25: 27989 | H25: false | I25: true | J25: true | K25: true | L25: 24990.18 | M25: 2026-09-02T12:19:00 | N25: 39032 | O25: Fulfilled | P25: Fully Paid | Q25: 4 | R25: YOKOHAMA 215/55/R16 BLUEARTH GT AE51 97W
A26: 2026-09-25 02:00:22 | B26: HANKOOK | D26: website | E26: Website | F26: 2026-09-02T14:15:00 | G26: 22019 | H26: false | I26: false | J26: false | K26: true | L26: 19659.82 | M26: 2026-09-02T13:21:00 | N26: 39034 | O26: New | P26: Unpaid | Q26: 4 | R26: HANKOOK 205/55/R17 VENTUS PRIME 4 95V
A27: 2026-09-25 02:00:22 | B27: HANKOOK | C27: Website | D27: website | E27: Website | F27: 2026-09-02T14:16:00 | G27: 22019 | H27: false | I27: false | J27: false | K27: true | L27: 19659.82 | M27: 2026-09-02T13:27:00 | N27: 39035 | O27: New | P27: Unpaid | Q27: 4 | R27: HANKOOK 205/55/R17 VENTUS PRIME 4 95V
A28: 2026-09-25 02:00:22 | B28: ARIVO | D28: website | E28: Website | F28: 2026-09-18T09:39:00 | G28: 2555 | H28: false | I28: true | J28: true | K28: true | L28: 2281.25 | M28: 2026-09-02T15:16:00 | N28: 39042 | O28: Fulfilled | P28: Fully Paid | Q28: 1 | R28: ARIVO 175/55/R15 PREMIO COMFORT 6
A29: 2026-09-25 02:00:22 | B29: BRIDGESTONE | C29: CALL | D29: website | E29: Website | F29: 2026-09-18T09:41:00 | G29: 17210.6 | H29: false | I29: true | J29: true | K29: true | L29: 15366.61 | M29: 2026-09-02T16:48:00 | N29: 39053 | O29: Fulfilled | P29: Fully Paid | Q29: 2 | R29: BRIDGESTONE 205/50/R17 TURANZA T005A
A30: 2026-09-25 02:00:22 | B30: BFGOODRICH | C30: Website | D30: website | E30: Website | F30: 2026-09-14T15:06:00 | G30: 21280.2 | H30: false | I30: true | J30: true | K30: true | L30: 19000.18 | M30: 2026-09-02T17:18:00 | N30: 39057 | O30: Fulfilled | P30: Fully Paid | Q30: 4 | R30: BFGOODRICH 215/55/R17 ADVANTAGE TOURING 94V
A31: 2026-09-25 02:00:22 | B31: HANKOOK | C31: Website | D31: website | E31: Website | F31: 2026-09-23T16:25:00 | G31: 21380.2 | H31: false | I31: false | J31: false | K31: false | L31: 19089.46 | M31: 2026-09-02T18:07:00 | N31: 39061 | O31: Cancelled | P31: Pending | Q31: 4 | R31: HANKOOK 215/55/R17 VENTUS PRIME 4 94W
A32: 2026-09-25 02:00:22 | B32: BRIDGESTONE | D32: website | E32: Website | F32: 2026-09-18T09:40:00 | G32: 6110 | H32: false | I32: true | J32: true | K32: true | L32: 5455.36 | M32: 2026-09-02T20:34:00 | N32: 39063 | O32: Fulfilled | P32: Fully Paid | Q32: 1 | R32: BRIDGESTONE 195/60/R16 ECOPIA EP150 89H
A33: 2026-09-25 02:00:22 | B33: DUNLOP | D33: website | E33: Website | F33: 2026-09-22T11:23:00 | G33: 47302.2 | H33: false | I33: true | J33: true | K33: true | L33: 42234.11 | M33: 2026-09-02T21:15:00 | N33: 39065 | O33: Fulfilled | P33: Fully Paid | Q33: 4 | R33: DUNLOP 265/50/R20 GRANDTREK PT5 107V
A34: 2026-09-25 02:00:22 | B34: BRIDGESTONE | C34: Website | D34: website | E34: Website | F34: 2026-09-23T16:25:00 | G34: 10750 | H34: false | I34: false | J34: false | K34: false | L34: 9598.21 | M34: 2026-09-02T21:34:00 | N34: 39066 | O34: Cancelled | P34: Pending | Q34: 1 | R34: BRIDGESTONE 265/65/R17 DUELER H/T 684 (RBT) 112S
A35: 2026-09-25 02:00:22 | B35: HANKOOK | C35: Website | D35: website | E35: Website | F35: 2026-09-04T14:42:00 | G35: 22019 | H35: false | I35: false | J35: false | K35: true | L35: 19659.82 | M35: 2026-09-02T23:57:00 | N35: 39068 | O35: New | P35: Unpaid | Q35: 4 | R35: HANKOOK 205/55/R17 VENTUS PRIME 4 95V
A36: 2026-09-25 02:00:22 | B36: BFGOODRICH | C36: Website | D36: website | E36: Website | F36: 2026-09-10T16:27:00 | G36: 14850 | H36: false | I36: false | J36: false | K36: false | L36: 13258.93 | M36: 2026-09-03T08:35:00 | N36: 39071 | O36: Cancelled | P36: Pending | Q36: 4 | R36: BFGOODRICH 185/55/R15 ADVANTAGE TOURING 86V
A37: 2026-09-25 02:00:22 | B37: MICHELIN | C37: Website | D37: website | E37: Website | F37: 2026-09-08T21:07:00 | G37: 50010 | H37: false | I37: true | J37: true | K37: true | L37: 44651.79 | M37: 2026-09-03T10:11:00 | N37: 39075 | O37: Fulfilled | P37: Fully Paid | Q37: 4 | R37: MICHELIN 235/60/R18 PILOT SPORT 4 SUV 107W
A38: 2026-09-25 02:00:22 | B38: LAUFENN | C38: Website | D38: website | E38: Website | F38: 2026-09-23T16:25:00 | G38: 21419 | H38: false | I38: false | J38: false | K38: false | L38: 19124.11 | M38: 2026-09-03T12:11:00 | N38: 39081 | O38: Cancelled | P38: Pending | Q38: 4 | R38: LAUFENN 225/65/R17 X FIT HT 102T
A39: 2026-09-25 02:00:22 | B39: BFGOODRICH | C39: Website | D39: website | E39: Website | F39: 2026-09-23T16:25:00 | G39: 15645.4 | H39: false | I39: false | J39: false | K39: false | L39: 13969.11 | M39: 2026-09-03T17:13:00 | N39: 39085 | O39: Cancelled | P39: Pending | Q39: 4 | R39: BFGOODRICH 195/55/R15 ADVANTAGE TOURING 89V
A40: 2026-09-25 02:00:22 | B40: BFGOODRICH | D40: website | E40: Website | F40: 2026-09-23T16:24:00 | G40: 17003.4 | H40: false | I40: false | J40: false | K40: false | L40: 15181.61 | M40: 2026-09-03T17:55:00 | N40: 39088 | O40: Cancelled | P40: Pending | Q40: 4 | R40: BFGOODRICH 195/60/R16 ADVANTAGE TOURING 89H
...

Sheet Exceptions
A1: Channel | B1: Session campaign | C1: Order ID | D1: Order date | E1: Week | F1: Scope | G1: Customer type | H1: Customer source | I1: Order status | J1: Payment status | K1: Net sales | L1: Fulfilled net revenue | M1: Gross order value | N1: Fulfilled flag | O1: Cancelled flag | P1: Open net value | Q1: Cancelled net value | R1: Return refund net value | S1: Purchase events | T1: Quantity | U1: Brand | V1: SKU | W1: Page path + query string | X1: Source file | Y1: Source CSV row | Z1: Backend loaded at | AA1: Backend updated at | AB1: Test order
A2: Google Ads | B2: Michelin - PMax PH | C2: 38959 | D2: 46265.788 | E2: Outside / unknown | F2: Outside period | G2: Website | H2: Website | I2: Fulfilled | J2: Fully Paid | K2: 27053.57 | L2: 27053.57 | M2: 30300 | N2: 1 | O2: 0 | P2: 0 | Q2: 0 | R2: 0 | S2: 2 | T2: 4 | U2: MICHELIN | V2: MICHELIN 195/60/R16 PRIMACY 5 93V | W2: /complete-order?requestid=Mzg5NTk= | X2: revenue_match/google_cpc.csv | Y2: 36 | Z2: 2026-09-25 02:00:22 | AA2: 2026-09-22T16:14:00 | AB2: false
A3: Direct & Organic | B3: (direct) | C3: 39900 | E3: Outside / unknown | F3: Unmatched | G3: Unknown | H3: Unknown | I3: Unknown | J3: Unknown | N3: 0 | O3: 0 | S3: 2 | W3: /complete-order?requestid=Mzk5MDA= | X3: direct_and_organic_revenue/direct_and_organic.csv | Y3: 64 | AB3: Unknown
A4: Direct & Organic | B4: (direct) | C4: 39109 | E4: Outside / unknown | F4: Unmatched | G4: Unknown | H4: Unknown | I4: Unknown | J4: Unknown | N4: 0 | O4: 0 | S4: 2 | W4: /complete-order?requestid=MzkxMDk= | X4: direct_and_organic_revenue/direct_and_organic.csv | Y4: 75 | AB4: Unknown
A5: Direct & Organic | B5: (direct) | C5: 38805 | D5: 46260.621 | E5: Outside / unknown | F5: Outside period | G5: Fb | H5: CALL | I5: Fulfilled | J5: Fully Paid | K5: 54174.11 | L5: 54174.11 | M5: 60675 | N5: 1 | O5: 0 | P5: 0 | Q5: 0 | R5: 0 | S5: 2 | T5: 4 | U5: MICHELIN | V5: MICHELIN 225/45/ZR19 PILOT SPORT 5 96Y XL TL | W5: /complete-order?requestid=Mzg4MDU= | X5: direct_and_organic_revenue/direct_and_organic.csv | Y5: 87 | Z5: 2026-09-25 02:00:22 | AA5: 2026-09-18T09:53:00 | AB5: false
A6: Direct & Organic | B6: (direct) | C6: 39052 | E6: Outside / unknown | F6: Unmatched | G6: Unknown | H6: Unknown | I6: Unknown | J6: Unknown | N6: 0 | O6: 0 | S6: 1 | W6: /complete-order?requestid=MzkwNTI= | X6: direct_and_organic_revenue/direct_and_organic.csv | Y6: 144 | AB6: Unknown

Sheet Channel Summary
A1: Channel Summary
A3: September 1–24 only. Order values are counted once; status reflects the backend snapshot.
A6: Channel | B6: Orders | C6: Net sales | D6: Fulfilled orders | E6: Fulfilled net revenue | F6: Fulfillment rate | G6: Cancelled orders | H6: Cancelled net value | I6: Open net value | J6: Return refund net value | K6: Net value per order | L6: Fulfilled value share
A7: Google Ads | B7: =COUNTIFS('Source Data'!$F$2:$F$268,"Included",'Source Data'!$A$2:$A$268,"Google Ads") -> 67 | C7: =SUMIFS('Source Data'!$K$2:$K$268,'Source Data'!$F$2:$F$268,"Included",'Source Data'!$A$2:$A$268,"Google Ads") -> 1473109.5 | D7: =SUMIFS('Source Data'!$N$2:$N$268,'Source Data'!$F$2:$F$268,"Included",'Source Data'!$A$2:$A$268,"Google Ads") -> 26 | E7: =SUMIFS('Source Data'!$L$2:$L$268,'Source Data'!$F$2:$F$268,"Included",'Source Data'!$A$2:$A$268,"Google Ads") -> 510707.5 | F7: =IFERROR(D7/B7,0) -> 0.3880597 | G7: =SUMIFS('Source Data'!$O$2:$O$268,'Source Data'!$F$2:$F$268,"Included",'Source Data'!$A$2:$A$268,"Google Ads") -> 18 | H7: =SUMIFS('Source Data'!$Q$2:$Q$268,'Source Data'!$F$2:$F$268,"Included",'Source Data'!$A$2:$A$268,"Google Ads") -> 328191.94 | I7: =SUMIFS('Source Data'!$P$2:$P$268,'Source Data'!$F$2:$F$268,"Included",'Source Data'!$A$2:$A$268,"Google Ads") -> 623269.5 | J7: =SUMIFS('Source Data'!$R$2:$R$268,'Source Data'!$F$2:$F$268,"Included",'Source Data'!$A$2:$A$268,"Google Ads") -> 10940.54 | K7: =IFERROR(C7/B7,0) -> 21986.709 | L7: =IFERROR(E7/C7,0) -> 0.34668672
A8: Direct & Organic | B8: =COUNTIFS('Source Data'!$F$2:$F$268,"Included",'Source Data'!$A$2:$A$268,"Direct & Organic") -> 167 | C8: =SUMIFS('Source Data'!$K$2:$K$268,'Source Data'!$F$2:$F$268,"Included",'Source Data'!$A$2:$A$268,"Direct & Organic") -> 2862122.7 | D8: =SUMIFS('Source Data'!$N$2:$N$268,'Source Data'!$F$2:$F$268,"Included",'Source Data'!$A$2:$A$268,"Direct & Organic") -> 75 | E8: =SUMIFS('Source Data'!$L$2:$L$268,'Source Data'!$F$2:$F$268,"Included",'Source Data'!$A$2:$A$268,"Direct & Organic") -> 1307528.9 | F8: =IFERROR(D8/B8,0) -> 0.4491018 | G8: =SUMIFS('Source Data'!$O$2:$O$268,'Source Data'!$F$2:$F$268,"Included",'Source Data'!$A$2:$A$268,"Direct & Organic") -> 50 | H8: =SUMIFS('Source Data'!$Q$2:$Q$268,'Source Data'!$F$2:$F$268,"Included",'Source Data'!$A$2:$A$268,"Direct & Organic") -> 833341.14 | I8: =SUMIFS('Source Data'!$P$2:$P$268,'Source Data'!$F$2:$F$268,"Included",'Source Data'!$A$2:$A$268,"Direct & Organic") -> 660976.6 | J8: =SUMIFS('Source Data'!$R$2:$R$268,'Source Data'!$F$2:$F$268,"Included",'Source Data'!$A$2:$A$268,"Direct & Organic") -> 60276.07 | K8: =IFERROR(C8/B8,0) -> 17138.459 | L8: =IFERROR(E8/C8,0) -> 0.45683886
A9: Referral | B9: =COUNTIFS('Source Data'!$F$2:$F$268,"Included",'Source Data'!$A$2:$A$268,"Referral") -> 28 | C9: =SUMIFS('Source Data'!$K$2:$K$268,'Source Data'!$F$2:$F$268,"Included",'Source Data'!$A$2:$A$268,"Referral") -> 464584.11 | D9: =SUMIFS('Source Data'!$N$2:$N$268,'Source Data'!$F$2:$F$268,"Included",'Source Data'!$A$2:$A$268,"Referral") -> 10 | E9: =SUMIFS('Source Data'!$L$2:$L$268,'Source Data'!$F$2:$F$268,"Included",'Source Data'!$A$2:$A$268,"Referral") -> 273228.94 | F9: =IFERROR(D9/B9,0) -> 0.35714286 | G9: =SUMIFS('Source Data'!$O$2:$O$268,'Source Data'!$F$2:$F$268,"Included",'Source Data'!$A$2:$A$268,"Referral") -> 11 | H9: =SUMIFS('Source Data'!$Q$2:$Q$268,'Source Data'!$F$2:$F$268,"Included",'Source Data'!$A$2:$A$268,"Referral") -> 132243.91 | I9: =SUMIFS('Source Data'!$P$2:$P$268,'Source Data'!$F$2:$F$268,"Included",'Source Data'!$A$2:$A$268,"Referral") -> 48170.72 | J9: =SUMIFS('Source Data'!$R$2:$R$268,'Source Data'!$F$2:$F$268,"Included",'Source Data'!$A$2:$A$268,"Referral") -> 10940.54 | K9: =IFERROR(C9/B9,0) -> 16592.29 | L9: =IFERROR(E9/C9,0) -> 0.58811512

Sheet Weekly Summary
A1: Weekly Summary
A3: September 1–24 only. Order values are counted once; status reflects the backend snapshot.
A6: Week | B6: Channel | C6: Orders | D6: Net sales | E6: Fulfilled orders | F6: Fulfilled net revenue | G6: Fulfillment rate | H6: Cancelled orders | I6: Cancelled net value | J6: Open net value | K6: Return refund net value | L6: Net value per order | M6: Fulfilled value share
A7: Week 1 | B7: Google Ads | C7: =COUNTIFS('Source Data'!$F$2:$F$268,"Included",'Source Data'!$E$2:$E$268,"Week 1",'Source Data'!$A$2:$A$268,"Google Ads") -> 24 | D7: =SUMIFS('Source Data'!$K$2:$K$268,'Source Data'!$F$2:$F$268,"Included",'Source Data'!$E$2:$E$268,"Week 1",'Source Data'!$A$2:$A$268,"Google Ads") -> 522608.31 | E7: =SUMIFS('Source Data'!$N$2:$N$268,'Source Data'!$F$2:$F$268,"Included",'Source Data'!$E$2:$E$268,"Week 1",'Source Data'!$A$2:$A$268,"Google Ads") -> 15 | F7: =SUMIFS('Source Data'!$L$2:$L$268,'Source Data'!$F$2:$F$268,"Included",'Source Data'!$E$2:$E$268,"Week 1",'Source Data'!$A$2:$A$268,"Google Ads") -> 324575.99 | G7: =IFERROR(E7/C7,0) -> 0.625 | H7: =SUMIFS('Source Data'!$O$2:$O$268,'Source Data'!$F$2:$F$268,"Included",'Source Data'!$E$2:$E$268,"Week 1",'Source Data'!$A$2:$A$268,"Google Ads") -> 6 | I7: =SUMIFS('Source Data'!$Q$2:$Q$268,'Source Data'!$F$2:$F$268,"Included",'Source Data'!$E$2:$E$268,"Week 1",'Source Data'!$A$2:$A$268,"Google Ads") -> 112916.25 | J7: =SUMIFS('Source Data'!$P$2:$P$268,'Source Data'!$F$2:$F$268,"Included",'Source Data'!$E$2:$E$268,"Week 1",'Source Data'!$A$2:$A$268,"Google Ads") -> 85116.07 | K7: =SUMIFS('Source Data'!$R$2:$R$268,'Source Data'!$F$2:$F$268,"Included",'Source Data'!$E$2:$E$268,"Week 1",'Source Data'!$A$2:$A$268,"Google Ads") -> 0 | L7: =IFERROR(D7/C7,0) -> 21775.346 | M7: =IFERROR(F7/D7,0) -> 0.62106932
A8: Week 1 | B8: Direct & Organic | C8: =COUNTIFS('Source Data'!$F$2:$F$268,"Included",'Source Data'!$E$2:$E$268,"Week 1",'Source Data'!$A$2:$A$268,"Direct & Organic") -> 52 | D8: =SUMIFS('Source Data'!$K$2:$K$268,'Source Data'!$F$2:$F$268,"Included",'Source Data'!$E$2:$E$268,"Week 1",'Source Data'!$A$2:$A$268,"Direct & Organic") -> 793046.8 | E8: =SUMIFS('Source Data'!$N$2:$N$268,'Source Data'!$F$2:$F$268,"Included",'Source Data'!$E$2:$E$268,"Week 1",'Source Data'!$A$2:$A$268,"Direct & Organic") -> 27 | F8: =SUMIFS('Source Data'!$L$2:$L$268,'Source Data'!$F$2:$F$268,"Included",'Source Data'!$E$2:$E$268,"Week 1",'Source Data'!$A$2:$A$268,"Direct & Organic") -> 403835.56 | G8: =IFERROR(E8/C8,0) -> 0.51923077 | H8: =SUMIFS('Source Data'!$O$2:$O$268,'Source Data'!$F$2:$F$268,"Included",'Source Data'!$E$2:$E$268,"Week 1",'Source Data'!$A$2:$A$268,"Direct & Organic") -> 21 | I8: =SUMIFS('Source Data'!$Q$2:$Q$268,'Source Data'!$F$2:$F$268,"Included",'Source Data'!$E$2:$E$268,"Week 1",'Source Data'!$A$2:$A$268,"Direct & Organic") -> 288772.84 | J8: =SUMIFS('Source Data'!$P$2:$P$268,'Source Data'!$F$2:$F$268,"Included",'Source Data'!$E$2:$E$268,"Week 1",'Source Data'!$A$2:$A$268,"Direct & Organic") -> 100438.4 | K8: =SUMIFS('Source Data'!$R$2:$R$268,'Source Data'!$F$2:$F$268,"Included",'Source Data'!$E$2:$E$268,"Week 1",'Source Data'!$A$2:$A$268,"Direct & Organic") -> 0 | L8: =IFERROR(D8/C8,0) -> 15250.9 | M8: =IFERROR(F8/D8,0) -> 0.50922034
A9: Week 1 | B9: Referral | C9: =COUNTIFS('Source Data'!$F$2:$F$268,"Included",'Source Data'!$E$2:$E$268,"Week 1",'Source Data'!$A$2:$A$268,"Referral") -> 5 | D9: =SUMIFS('Source Data'!$K$2:$K$268,'Source Data'!$F$2:$F$268,"Included",'Source Data'!$E$2:$E$268,"Week 1",'Source Data'!$A$2:$A$268,"Referral") -> 90845.09 | E9: =SUMIFS('Source Data'!$N$2:$N$268,'Source Data'!$F$2:$F$268,"Included",'Source Data'!$E$2:$E$268,"Week 1",'Source Data'!$A$2:$A$268,"Referral") -> 2 | F9: =SUMIFS('Source Data'!$L$2:$L$268,'Source Data'!$F$2:$F$268,"Included",'Source Data'!$E$2:$E$268,"Week 1",'Source Data'!$A$2:$A$268,"Referral") -> 76986.61 | G9: =IFERROR(E9/C9,0) -> 0.4 | H9: =SUMIFS('Source Data'!$O$2:$O$268,'Source Data'!$F$2:$F$268,"Included",'Source Data'!$E$2:$E$268,"Week 1",'Source Data'!$A$2:$A$268,"Referral") -> 2 | I9: =SUMIFS('Source Data'!$Q$2:$Q$268,'Source Data'!$F$2:$F$268,"Included",'Source Data'!$E$2:$E$268,"Week 1",'Source Data'!$A$2:$A$268,"Referral") -> 7907.59 | J9: =SUMIFS('Source Data'!$P$2:$P$268,'Source Data'!$F$2:$F$268,"Included",'Source Data'!$E$2:$E$268,"Week 1",'Source Data'!$A$2:$A$268,"Referral") -> 5950.89 | K9: =SUMIFS('Source Data'!$R$2:$R$268,'Source Data'!$F$2:$F$268,"Included",'Source Data'!$E$2:$E$268,"Week 1",'Source Data'!$A$2:$A$268,"Referral") -> 0 | L9: =IFERROR(D9/C9,0) -> 18169.018 | M9: =IFERROR(F9/D9,0) -> 0.84744932
A10: Week 2 | B10: Google Ads | C10: =COUNTIFS('Source Data'!$F$2:$F$268,"Included",'Source Data'!$E$2:$E$268,"Week 2",'Source Data'!$A$2:$A$268,"Google Ads") -> 12 | D10: =SUMIFS('Source Data'!$K$2:$K$268,'Source Data'!$F$2:$F$268,"Included",'Source Data'!$E$2:$E$268,"Week 2",'Source Data'!$A$2:$A$268,"Google Ads") -> 232561.16 | E10: =SUMIFS('Source Data'!$N$2:$N$268,'Source Data'!$F$2:$F$268,"Included",'Source Data'!$E$2:$E$268,"Week 2",'Source Data'!$A$2:$A$268,"Google Ads") -> 4 | F10: =SUMIFS('Source Data'!$L$2:$L$268,'Source Data'!$F$2:$F$268,"Included",'Source Data'!$E$2:$E$268,"Week 2",'Source Data'!$A$2:$A$268,"Google Ads") -> 85278.66 | G10: =IFERROR(E10/C10,0) -> 0.33333333 | H10: =SUMIFS('Source Data'!$O$2:$O$268,'Source Data'!$F$2:$F$268,"Included",'Source Data'!$E$2:$E$268,"Week 2",'Source Data'!$A$2:$A$268,"Google Ads") -> 4 | I10: =SUMIFS('Source Data'!$Q$2:$Q$268,'Source Data'!$F$2:$F$268,"Included",'Source Data'!$E$2:$E$268,"Week 2",'Source Data'!$A$2:$A$268,"Google Ads") -> 81415.88 | J10: =SUMIFS('Source Data'!$P$2:$P$268,'Source Data'!$F$2:$F$268,"Included",'Source Data'!$E$2:$E$268,"Week 2",'Source Data'!$A$2:$A$268,"Google Ads") -> 65866.62 | K10: =SUMIFS('Source Data'!$R$2:$R$268,'Source Data'!$F$2:$F$268,"Included",'Source Data'!$E$2:$E$268,"Week 2",'Source Data'!$A$2:$A$268,"Google Ads") -> 0 | L10: =IFERROR(D10/C10,0) -> 19380.097 | M10: =IFERROR(F10/D10,0) -> 0.36669348
A11: Week 2 | B11: Direct & Organic | C11: =COUNTIFS('Source Data'!$F$2:$F$268,"Included",'Source Data'!$E$2:$E$268,"Week 2",'Source Data'!$A$2:$A$268,"Direct & Organic") -> 58 | D11: =SUMIFS('Source Data'!$K$2:$K$268,'Source Data'!$F$2:$F$268,"Included",'Source Data'!$E$2:$E$268,"Week 2",'Source Data'!$A$2:$A$268,"Direct & Organic") -> 1071885 | E11: =SUMIFS('Source Data'!$N$2:$N$268,'Source Data'!$F$2:$F$268,"Included",'Source Data'!$E$2:$E$268,"Week 2",'Source Data'!$A$2:$A$268,"Direct & Organic") -> 30 | F11: =SUMIFS('Source Data'!$L$2:$L$268,'Source Data'!$F$2:$F$268,"Included",'Source Data'!$E$2:$E$268,"Week 2",'Source Data'!$A$2:$A$268,"Direct & Organic") -> 601332.86 | G11: =IFERROR(E11/C11,0) -> 0.51724138 | H11: =SUMIFS('Source Data'!$O$2:$O$268,'Source Data'!$F$2:$F$268,"Included",'Source Data'!$E$2:$E$268,"Week 2",'Source Data'!$A$2:$A$268,"Direct & Organic") -> 17 | I11: =SUMIFS('Source Data'!$Q$2:$Q$268,'Source Data'!$F$2:$F$268,"Included",'Source Data'!$E$2:$E$268,"Week 2",'Source Data'!$A$2:$A$268,"Direct & Organic") -> 312359.55 | J11: =SUMIFS('Source Data'!$P$2:$P$268,'Source Data'!$F$2:$F$268,"Included",'Source Data'!$E$2:$E$268,"Week 2",'Source Data'!$A$2:$A$268,"Direct & Organic") -> 126891.49 | K11: =SUMIFS('Source Data'!$R$2:$R$268,'Source Data'!$F$2:$F$268,"Included",'Source Data'!$E$2:$E$268,"Week 2",'Source Data'!$A$2:$A$268,"Direct & Organic") -> 31301.07 | L11: =IFERROR(D11/C11,0) -> 18480.775 | M11: =IFERROR(F11/D11,0) -> 0.56100503
A12: Week 2 | B12: Referral | C12: =COUNTIFS('Source Data'!$F$2:$F$268,"Included",'Source Data'!$E$2:$E$268,"Week 2",'Source Data'!$A$2:$A$268,"Referral") -> 13 | D12: =SUMIFS('Source Data'!$K$2:$K$268,'Source Data'!$F$2:$F$268,"Included",'Source Data'!$E$2:$E$268,"Week 2",'Source Data'!$A$2:$A$268,"Referral") -> 208630.37 | E12: =SUMIFS('Source Data'!$N$2:$N$268,'Source Data'!$F$2:$F$268,"Included",'Source Data'!$E$2:$E$268,"Week 2",'Source Data'!$A$2:$A$268,"Referral") -> 5 | F12: =SUMIFS('Source Data'!$L$2:$L$268,'Source Data'!$F$2:$F$268,"Included",'Source Data'!$E$2:$E$268,"Week 2",'Source Data'!$A$2:$A$268,"Referral") -> 125783.22 | G12: =IFERROR(E12/C12,0) -> 0.38461538 | H12: =SUMIFS('Source Data'!$O$2:$O$268,'Source Data'!$F$2:$F$268,"Included",'Source Data'!$E$2:$E$268,"Week 2",'Source Data'!$A$2:$A$268,"Referral") -> 3 | I12: =SUMIFS('Source Data'!$Q$2:$Q$268,'Source Data'!$F$2:$F$268,"Included",'Source Data'!$E$2:$E$268,"Week 2",'Source Data'!$A$2:$A$268,"Referral") -> 43421.96 | J12: =SUMIFS('Source Data'!$P$2:$P$268,'Source Data'!$F$2:$F$268,"Included",'Source Data'!$E$2:$E$268,"Week 2",'Source Data'!$A$2:$A$268,"Referral") -> 28484.65 | K12: =SUMIFS('Source Data'!$R$2:$R$268,'Source Data'!$F$2:$F$268,"Included",'Source Data'!$E$2:$E$268,"Week 2",'Source Data'!$A$2:$A$268,"Referral") -> 10940.54 | L12: =IFERROR(D12/C12,0) -> 16048.49 | M12: =IFERROR(F12/D12,0) -> 0.60289986
A13: Week 3 | B13: Google Ads | C13: =COUNTIFS('Source Data'!$F$2:$F$268,"Included",'Source Data'!$E$2:$E$268,"Week 3",'Source Data'!$A$2:$A$268,"Google Ads") -> 22 | D13: =SUMIFS('Source Data'!$K$2:$K$268,'Source Data'!$F$2:$F$268,"Included",'Source Data'!$E$2:$E$268,"Week 3",'Source Data'!$A$2:$A$268,"Google Ads") -> 552631.53 | E13: =SUMIFS('Source Data'!$N$2:$N$268,'Source Data'!$F$2:$F$268,"Included",'Source Data'!$E$2:$E$268,"Week 3",'Source Data'!$A$2:$A$268,"Google Ads") -> 7 | F13: =SUMIFS('Source Data'!$L$2:$L$268,'Source Data'!$F$2:$F$268,"Included",'Source Data'!$E$2:$E$268,"Week 3",'Source Data'!$A$2:$A$268,"Google Ads") -> 100852.85 | G13: =IFERROR(E13/C13,0) -> 0.31818182 | H13: =SUMIFS('Source Data'!$O$2:$O$268,'Source Data'!$F$2:$F$268,"Included",'Source Data'!$E$2:$E$268,"Week 3",'Source Data'!$A$2:$A$268,"Google Ads") -> 5 | I13: =SUMIFS('Source Data'!$Q$2:$Q$268,'Source Data'!$F$2:$F$268,"Included",'Source Data'!$E$2:$E$268,"Week 3",'Source Data'!$A$2:$A$268,"Google Ads") -> 70828.57 | J13: =SUMIFS('Source Data'!$P$2:$P$268,'Source Data'!$F$2:$F$268,"Included",'Source Data'!$E$2:$E$268,"Week 3",'Source Data'!$A$2:$A$268,"Google Ads") -> 370009.57 | K13: =SUMIFS('Source Data'!$R$2:$R$268,'Source Data'!$F$2:$F$268,"Included",'Source Data'!$E$2:$E$268,"Week 3",'Source Data'!$A$2:$A$268,"Google Ads") -> 10940.54 | L13: =IFERROR(D13/C13,0) -> 25119.615 | M13: =IFERROR(F13/D13,0) -> 0.18249565
A14: Week 3 | B14: Direct & Organic | C14: =COUNTIFS('Source Data'!$F$2:$F$268,"Included",'Source Data'!$E$2:$E$268,"Week 3",'Source Data'!$A$2:$A$268,"Direct & Organic") -> 41 | D14: =SUMIFS('Source Data'!$K$2:$K$268,'Source Data'!$F$2:$F$268,"Included",'Source Data'!$E$2:$E$268,"Week 3",'Source Data'!$A$2:$A$268,"Direct & Organic") -> 684801.78 | E14: =SUMIFS('Source Data'!$N$2:$N$268,'Source Data'!$F$2:$F$268,"Included",'Source Data'!$E$2:$E$268,"Week 3",'Source Data'!$A$2:$A$268,"Direct & Organic") -> 18 | F14: =SUMIFS('Source Data'!$L$2:$L$268,'Source Data'!$F$2:$F$268,"Included",'Source Data'!$E$2:$E$268,"Week 3",'Source Data'!$A$2:$A$268,"Direct & Organic") -> 302360.43 | G14: =IFERROR(E14/C14,0) -> 0.43902439 | H14: =SUMIFS('Source Data'!$O$2:$O$268,'Source Data'!$F$2:$F$268,"Included",'Source Data'!$E$2:$E$268,"Week 3",'Source Data'!$A$2:$A$268,"Direct & Organic") -> 11 | I14: =SUMIFS('Source Data'!$Q$2:$Q$268,'Source Data'!$F$2:$F$268,"Included",'Source Data'!$E$2:$E$268,"Week 3",'Source Data'!$A$2:$A$268,"Direct & Organic") -> 224396.61 | J14: =SUMIFS('Source Data'!$P$2:$P$268,'Source Data'!$F$2:$F$268,"Included",'Source Data'!$E$2:$E$268,"Week 3",'Source Data'!$A$2:$A$268,"Direct & Organic") -> 129069.74 | K14: =SUMIFS('Source Data'!$R$2:$R$268,'Source Data'!$F$2:$F$268,"Included",'Source Data'!$E$2:$E$268,"Week 3",'Source Data'!$A$2:$A$268,"Direct & Organic") -> 28975 | L14: =IFERROR(D14/C14,0) -> 16702.482 | M14: =IFERROR(F14/D14,0) -> 0.44152985
A15: Week 3 | B15: Referral | C15: =COUNTIFS('Source Data'!$F$2:$F$268,"Included",'Source Data'!$E$2:$E$268,"Week 3",'Source Data'!$A$2:$A$268,"Referral") -> 8 | D15: =SUMIFS('Source Data'!$K$2:$K$268,'Source Data'!$F$2:$F$268,"Included",'Source Data'!$E$2:$E$268,"Week 3",'Source Data'!$A$2:$A$268,"Referral") -> 134840.53 | E15: =SUMIFS('Source Data'!$N$2:$N$268,'Source Data'!$F$2:$F$268,"Included",'Source Data'!$E$2:$E$268,"Week 3",'Source Data'!$A$2:$A$268,"Referral") -> 3 | F15: =SUMIFS('Source Data'!$L$2:$L$268,'Source Data'!$F$2:$F$268,"Included",'Source Data'!$E$2:$E$268,"Week 3",'Source Data'!$A$2:$A$268,"Referral") -> 70459.11 | G15: =IFERROR(E15/C15,0) -> 0.375 | H15: =SUMIFS('Source Data'!$O$2:$O$268,'Source Data'!$F$2:$F$268,"Included",'Source Data'!$E$2:$E$268,"Week 3",'Source Data'!$A$2:$A$268,"Referral") -> 4 | I15: =SUMIFS('Source Data'!$Q$2:$Q$268,'Source Data'!$F$2:$F$268,"Included",'Source Data'!$E$2:$E$268,"Week 3",'Source Data'!$A$2:$A$268,"Referral") -> 50646.24 | J15: =SUMIFS('Source Data'!$P$2:$P$268,'Source Data'!$F$2:$F$268,"Included",'Source Data'!$E$2:$E$268,"Week 3",'Source Data'!$A$2:$A$268,"Referral") -> 13735.18 | K15: =SUMIFS('Source Data'!$R$2:$R$268,'Source Data'!$F$2:$F$268,"Included",'Source Data'!$E$2:$E$268,"Week 3",'Source Data'!$A$2:$A$268,"Referral") -> 0 | L15: =IFERROR(D15/C15,0) -> 16855.066 | M15: =IFERROR(F15/D15,0) -> 0.52253658
A16: Week 4 | B16: Google Ads | C16: =COUNTIFS('Source Data'!$F$2:$F$268,"Included",'Source Data'!$E$2:$E$268,"Week 4",'Source Data'!$A$2:$A$268,"Google Ads") -> 9 | D16: =SUMIFS('Source Data'!$K$2:$K$268,'Source Data'!$F$2:$F$268,"Included",'Source Data'!$E$2:$E$268,"Week 4",'Source Data'!$A$2:$A$268,"Google Ads") -> 165308.48 | E16: =SUMIFS('Source Data'!$N$2:$N$268,'Source Data'!$F$2:$F$268,"Included",'Source Data'!$E$2:$E$268,"Week 4",'Source Data'!$A$2:$A$268,"Google Ads") -> 0 | F16: =SUMIFS('Source Data'!$L$2:$L$268,'Source Data'!$F$2:$F$268,"Included",'Source Data'!$E$2:$E$268,"Week 4",'Source Data'!$A$2:$A$268,"Google Ads") -> 0 | G16: =IFERROR(E16/C16,0) -> 0 | H16: =SUMIFS('Source Data'!$O$2:$O$268,'Source Data'!$F$2:$F$268,"Included",'Source Data'!$E$2:$E$268,"Week 4",'Source Data'!$A$2:$A$268,"Google Ads") -> 3 | I16: =SUMIFS('Source Data'!$Q$2:$Q$268,'Source Data'!$F$2:$F$268,"Included",'Source Data'!$E$2:$E$268,"Week 4",'Source Data'!$A$2:$A$268,"Google Ads") -> 63031.24 | J16: =SUMIFS('Source Data'!$P$2:$P$268,'Source Data'!$F$2:$F$268,"Included",'Source Data'!$E$2:$E$268,"Week 4",'Source Data'!$A$2:$A$268,"Google Ads") -> 102277.24 | K16: =SUMIFS('Source Data'!$R$2:$R$268,'Source Data'!$F$2:$F$268,"Included",'Source Data'!$E$2:$E$268,"Week 4",'Source Data'!$A$2:$A$268,"Google Ads") -> 0 | L16: =IFERROR(D16/C16,0) -> 18367.609 | M16: =IFERROR(F16/D16,0) -> 0
A17: Week 4 | B17: Direct & Organic | C17: =COUNTIFS('Source Data'!$F$2:$F$268,"Included",'Source Data'!$E$2:$E$268,"Week 4",'Source Data'!$A$2:$A$268,"Direct & Organic") -> 16 | D17: =SUMIFS('Source Data'!$K$2:$K$268,'Source Data'!$F$2:$F$268,"Included",'Source Data'!$E$2:$E$268,"Week 4",'Source Data'!$A$2:$A$268,"Direct & Organic") -> 312389.11 | E17: =SUMIFS('Source Data'!$N$2:$N$268,'Source Data'!$F$2:$F$268,"Included",'Source Data'!$E$2:$E$268,"Week 4",'Source Data'!$A$2:$A$268,"Direct & Organic") -> 0 | F17: =SUMIFS('Source Data'!$L$2:$L$268,'Source Data'!$F$2:$F$268,"Included",'Source Data'!$E$2:$E$268,"Week 4",'Source Data'!$A$2:$A$268,"Direct & Organic") -> 0 | G17: =IFERROR(E17/C17,0) -> 0 | H17: =SUMIFS('Source Data'!$O$2:$O$268,'Source Data'!$F$2:$F$268,"Included",'Source Data'!$E$2:$E$268,"Week 4",'Source Data'!$A$2:$A$268,"Direct & Organic") -> 1 | I17: =SUMIFS('Source Data'!$Q$2:$Q$268,'Source Data'!$F$2:$F$268,"Included",'Source Data'!$E$2:$E$268,"Week 4",'Source Data'!$A$2:$A$268,"Direct & Organic") -> 7812.14 | J17: =SUMIFS('Source Data'!$P$2:$P$268,'Source Data'!$F$2:$F$268,"Included",'Source Data'!$E$2:$E$268,"Week 4",'Source Data'!$A$2:$A$268,"Direct & Organic") -> 304576.97 | K17: =SUMIFS('Source Data'!$R$2:$R$268,'Source Data'!$F$2:$F$268,"Included",'Source Data'!$E$2:$E$268,"Week 4",'Source Data'!$A$2:$A$268,"Direct & Organic") -> 0 | L17: =IFERROR(D17/C17,0) -> 19524.319 | M17: =IFERROR(F17/D17,0) -> 0
A18: Week 4 | B18: Referral | C18: =COUNTIFS('Source Data'!$F$2:$F$268,"Included",'Source Data'!$E$2:$E$268,"Week 4",'Source Data'!$A$2:$A$268,"Referral") -> 2 | D18: =SUMIFS('Source Data'!$K$2:$K$268,'Source Data'!$F$2:$F$268,"Included",'Source Data'!$E$2:$E$268,"Week 4",'Source Data'!$A$2:$A$268,"Referral") -> 30268.12 | E18: =SUMIFS('Source Data'!$N$2:$N$268,'Source Data'!$F$2:$F$268,"Included",'Source Data'!$E$2:$E$268,"Week 4",'Source Data'!$A$2:$A$268,"Referral") -> 0 | F18: =SUMIFS('Source Data'!$L$2:$L$268,'Source Data'!$F$2:$F$268,"Included",'Source Data'!$E$2:$E$268,"Week 4",'Source Data'!$A$2:$A$268,"Referral") -> 0 | G18: =IFERROR(E18/C18,0) -> 0 | H18: =SUMIFS('Source Data'!$O$2:$O$268,'Source Data'!$F$2:$F$268,"Included",'Source Data'!$E$2:$E$268,"Week 4",'Source Data'!$A$2:$A$268,"Referral") -> 2 | I18: =SUMIFS('Source Data'!$Q$2:$Q$268,'Source Data'!$F$2:$F$268,"Included",'Source Data'!$E$2:$E$268,"Week 4",'Source Data'!$A$2:$A$268,"Referral") -> 30268.12 | J18: =SUMIFS('Source Data'!$P$2:$P$268,'Source Data'!$F$2:$F$268,"Included",'Source Data'!$E$2:$E$268,"Week 4",'Source Data'!$A$2:$A$268,"Referral") -> 0 | K18: =SUMIFS('Source Data'!$R$2:$R$268,'Source Data'!$F$2:$F$268,"Included",'Source Data'!$E$2:$E$268,"Week 4",'Source Data'!$A$2:$A$268,"Referral") -> 0 | L18: =IFERROR(D18/C18,0) -> 15134.06 | M18: =IFERROR(F18/D18,0) -> 0

Sheet Customer Type
A1: Customer Type
