Workbook

Sheet Methodology
B1: Top 20 Tire Sizes & Patterns — 2025 & 2026
B2: Gulong.ph — methodology & data notes
B4: Source files
B5: 2025 source: "Gulong Operations Report_fb inquries daily_Table (2).csv" (1,614 SKU-pack rows). 2026 source remains the existing 2026 raw population.
B7: Count = total tires sold
B8: Count is the total tire quantity sold, not order rows. In the source, the last column (tire total) equals Pack Qty x Orders in 100% of rows, so a single order of 4 tires contributes +4. This value is carried into the Raw Data sheets as "Count (tires)".
B10: % Share of Year
B11: Year totals after source refresh: 2025 = 13,566 tires; 2026 = 10,903 tires. The 2025 total now reconciles exactly to the fulfilled category report.
B13: Tire size cleaning
B14: The source "tire size" column is used as-is where present. It was blank for ZR-rated sizes (e.g. 255/40ZR19), aspect-less van sizes and a few odd formats. Those were recovered from the SKU text and normalised to the same style (Z speed marking dropped; e.g. 255/40ZR19 -> 255/40/R19). Trailing "C" (commercial) follows the source convention. Only ~10-12 tires per year (~0.1%) had a size that could not be confidently parsed; these are left blank in "Final Size", so they drop out of the size ranking but still count in the Year Total (percentages stay honest).
B16: Tire pattern extraction
B17: Pattern is not a source column — it is embedded in the SKU (BRAND SIZE PATTERN LOAD/SPEED). It was derived by removing the brand prefix and the size, then stripping trailing load/speed specs (e.g. 110H, 102/100R) and modifiers (XL, TL, PR, TT). Genuine pattern codes are preserved: Westlake RP36 / SA37, Arivo PREMIO ARZ1, and names ending in a number such as PREMIO COMFORT 6. Patterns are not merged on similarity alone.
... B23: 2025 source replacement completed using the supplied operations-report CSV. Control: Pack Qty × Orders equals Count for every one of the 1,614 rows.

Sheet 2025 - Top 20 Sizes
A1: Rank | B1: Tire Size | C1: Count | D1: % Share of Year
A2: 1 | B2: 185/60/R15 | C2: 949 | D2: 0.069954298
A3: 2 | B3: 175/65/R14 | C3: 788 | D3: 0.058086392
A4: 3 | B4: 185/65/R15 | C4: 758 | D4: 0.055874982
A5: 4 | B5: 185/55/R15 | C5: 600 | D5: 0.044228218
A6: 5 | B6: 265/60/R18 | C6: 529 | D6: 0.038994545
A7: 6 | B7: 205/55/R16 | C7: 488 | D7: 0.035972284
A8: 7 | B8: 265/65/R17 | C8: 486 | D8: 0.035824856
A9: 8 | B9: 205/65/R16 | C9: 335 | D9: 0.024694088
A10: 9 | B10: 185/70/R14 | C10: 269 | D10: 0.019828984
A11: 10 | B11: 215/55/R17 | C11: 256 | D11: 0.018870706
A12: 11 | B12: 215/60/R17 | C12: 227 | D12: 0.016733009
A13: 12 | B13: 205/60/R16 | C13: 226 | D13: 0.016659295
... A21: 20 | B21: 265/50/R20 | C21: 184 | D21: 0.01356332
B22: Top 20 Subtotal | C22: 7523 | D22: 0.55454814
B23: Year Total | C23: 13566 | D23: 1

Sheet 2025 - Top 20 Patterns
A1: Rank | B1: Tire Pattern | C1: Count | D1: % Share of Year
A2: 1 | B2: PREMIO ARZ1 | C2: 1918 | D2: 0.14138287
A3: 2 | B3: ENERGY XM2+ | C3: 768 | D3: 0.056612119
A4: 3 | B4: PRIMACY SUV+ | C4: 648 | D4: 0.047766475
A5: 4 | B5: ALNAC 4G | C5: 631 | D5: 0.046513342
A6: 5 | B6: BLUEARTH ES32 | C6: 620 | D6: 0.045702492
A7: 6 | B7: PRIMACY 5 | C7: 397 | D7: 0.029264337
A8: 7 | B8: RP36 | C8: 388 | D8: 0.028600914
A9: 8 | B9: ULTRA ARZ4 | C9: 289 | D9: 0.021303258
A10: 9 | B10: ECOGREEN 66 | C10: 281 | D10: 0.020713549
A11: 10 | B11: PRIMACY 4 ST | C11: 258 | D11: 0.019018134
A12: 11 | B12: SA37 | C12: 253 | D12: 0.018649565
A13: 12 | B13: ECOPIA EP300 | C13: 249 | D13: 0.01835471
... A21: 20 | B21: RP26 | C21: 169 | D21: 0.012457615
B22: Top 20 Subtotal | C22: 8302 | D22: 0.6119711
B23: Year Total | C23: 13566 | D23: 1

Sheet 2026 - Top 20 Sizes
A1: Rank | B1: Tire Size | C1: Count | D1: % Share of Year
A2: 1 | B2: 185/60/R15 | C2: =SUMIF('2026 - Raw Data'!$D:$D,B2,'2026 - Raw Data'!$H:$H) | D2: =C2/$C$23
A3: 2 | B3: 175/65/R14 | C3: =SUMIF('2026 - Raw Data'!$D:$D,B3,'2026 - Raw Data'!$H:$H) | D3: =C3/$C$23
A4: 3 | B4: 185/65/R15 | C4: =SUMIF('2026 - Raw Data'!$D:$D,B4,'2026 - Raw Data'!$H:$H) | D4: =C4/$C$23
A5: 4 | B5: 185/55/R15 | C5: =SUMIF('2026 - Raw Data'!$D:$D,B5,'2026 - Raw Data'!$H:$H) | D5: =C5/$C$23
A6: 5 | B6: 265/60/R18 | C6: =SUMIF('2026 - Raw Data'!$D:$D,B6,'2026 - Raw Data'!$H:$H) | D6: =C6/$C$23
A7: 6 | B7: 205/55/R16 | C7: =SUMIF('2026 - Raw Data'!$D:$D,B7,'2026 - Raw Data'!$H:$H) | D7: =C7/$C$23
A8: 7 | B8: 265/65/R17 | C8: =SUMIF('2026 - Raw Data'!$D:$D,B8,'2026 - Raw Data'!$H:$H) | D8: =C8/$C$23
A9: 8 | B9: 215/60/R17 | C9: =SUMIF('2026 - Raw Data'!$D:$D,B9,'2026 - Raw Data'!$H:$H) | D9: =C9/$C$23
A10: 9 | B10: 205/65/R16 | C10: =SUMIF('2026 - Raw Data'!$D:$D,B10,'2026 - Raw Data'!$H:$H) | D10: =C10/$C$23
A11: 10 | B11: 215/55/R17 | C11: =SUMIF('2026 - Raw Data'!$D:$D,B11,'2026 - Raw Data'!$H:$H) | D11: =C11/$C$23
A12: 11 | B12: 195/60/R16 | C12: =SUMIF('2026 - Raw Data'!$D:$D,B12,'2026 - Raw Data'!$H:$H) | D12: =C12/$C$23
A13: 12 | B13: 205/60/R16 | C13: =SUMIF('2026 - Raw Data'!$D:$D,B13,'2026 - Raw Data'!$H:$H) | D13: =C13/$C$23
... A21: 20 | B21: 235/60/R18 | C21: =SUMIF('2026 - Raw Data'!$D:$D,B21,'2026 - Raw Data'!$H:$H) | D21: =C21/$C$23
B22: Top 20 Total | C22: =SUM(C2:C21) | D22: =C22/$C$23
B23: Year Total (all tires) | C23: =SUM('2026 - Raw Data'!$H:$H) | D23: 1

Sheet 2026 - Top 20 Patterns
A1: Rank | B1: Tire Pattern | C1: Count | D1: % Share of Year
A2: 1 | B2: ADVANTAGE TOURING | C2: =SUMIF('2026 - Raw Data'!$E:$E,B2,'2026 - Raw Data'!$H:$H) | D2: =C2/$C$23
A3: 2 | B3: PRIMACY 5 | C3: =SUMIF('2026 - Raw Data'!$E:$E,B3,'2026 - Raw Data'!$H:$H) | D3: =C3/$C$23
A4: 3 | B4: PREMIO COMFORT 6 | C4: =SUMIF('2026 - Raw Data'!$E:$E,B4,'2026 - Raw Data'!$H:$H) | D4: =C4/$C$23
A5: 4 | B5: ENERGY XM2+ | C5: =SUMIF('2026 - Raw Data'!$E:$E,B5,'2026 - Raw Data'!$H:$H) | D5: =C5/$C$23
A6: 5 | B6: PRIMACY SUV+ | C6: =SUMIF('2026 - Raw Data'!$E:$E,B6,'2026 - Raw Data'!$H:$H) | D6: =C6/$C$23
A7: 6 | B7: ECOGREEN ONE | C7: =SUMIF('2026 - Raw Data'!$E:$E,B7,'2026 - Raw Data'!$H:$H) | D7: =C7/$C$23
A8: 7 | B8: RP36 | C8: =SUMIF('2026 - Raw Data'!$E:$E,B8,'2026 - Raw Data'!$H:$H) | D8: =C8/$C$23
A9: 8 | B9: BLUEARTH ES32 | C9: =SUMIF('2026 - Raw Data'!$E:$E,B9,'2026 - Raw Data'!$H:$H) | D9: =C9/$C$23
A10: 9 | B10: G FIT AS | C10: =SUMIF('2026 - Raw Data'!$E:$E,B10,'2026 - Raw Data'!$H:$H) | D10: =C10/$C$23
A11: 10 | B11: PILOT SPORT 5 | C11: =SUMIF('2026 - Raw Data'!$E:$E,B11,'2026 - Raw Data'!$H:$H) | D11: =C11/$C$23
A12: 11 | B12: ECOPIA EP300 | C12: =SUMIF('2026 - Raw Data'!$E:$E,B12,'2026 - Raw Data'!$H:$H) | D12: =C12/$C$23
A13: 12 | B13: SA37 | C13: =SUMIF('2026 - Raw Data'!$E:$E,B13,'2026 - Raw Data'!$H:$H) | D13: =C13/$C$23
... A21: 20 | B21: PREMIO ARZ1 | C21: =SUMIF('2026 - Raw Data'!$E:$E,B21,'2026 - Raw Data'!$H:$H) | D21: =C21/$C$23
B22: Top 20 Total | C22: =SUM(C2:C21) | D22: =C22/$C$23
B23: Year Total (all tires) | C23: =SUM('2026 - Raw Data'!$H:$H) | D23: 1

Sheet 2025 - Raw Data
A1: Brand | B1: SKU | C1: Original Size | D1: Final Size (used) | E1: Pattern (extracted) | F1: Pack Qty | G1: Orders | H1: Count (tires)
A2: MICHELIN | B2: MICHELIN 265/60/R18 PRIMACY SUV+ 110H | C2: 265/60/R18 | D2: 265/60/R18 | E2: PRIMACY SUV+ | F2: 4 | G2: 32 | H2: 128
A3: MICHELIN | B3: MICHELIN 265/65/R17 PRIMACY SUV+ 112H | C3: 265/65/R17 | D3: 265/65/R17 | E3: PRIMACY SUV+ | F3: 4 | G3: 34 | H3: 136
A4: MICHELIN | B4: MICHELIN 265/50/R20 PILOT SPORT 4 SUV 107V | C4: 265/50/R20 | D4: 265/50/R20 | E4: PILOT SPORT 4 SUV | F4: 4 | G4: 18 | H4: 72
A5: MICHELIN | B5: MICHELIN 225/55/R18 PRIMACY 5 102V | C5: 225/55/R18 | D5: 225/55/R18 | E5: PRIMACY 5 | F5: 4 | G5: 18 | H5: 72
A6: MICHELIN | B6: MICHELIN 185/60/R15 ENERGY XM2+ 88H | C6: 185/60/R15 | D6: 185/60/R15 | E6: ENERGY XM2+ | F6: 4 | G6: 38 | H6: 152
A7: MICHELIN | B7: MICHELIN 225/55/R19 PRIMACY SUV+ 99V | C7: 225/55/R19 | D7: 225/55/R19 | E7: PRIMACY SUV+ | F7: 4 | G7: 15 | H7: 60
A8: YOKOHAMA | B8: YOKOHAMA 185/60/R15 BLUEARTH ES32 84H | C8: 185/60/R15 | D8: 185/60/R15 | E8: BLUEARTH ES32 | F8: 4 | G8: 33 | H8: 132
A9: MICHELIN | B9: MICHELIN 205/55/R16 ENERGY XM2+ 91V | C9: 205/55/R16 | D9: 205/55/R16 | E9: ENERGY XM2+ | F9: 4 | G9: 25 | H9: 100
A10: APOLLO | B10: APOLLO 185/60/R15 ALNAC 4G 84H | C10: 185/60/R15 | D10: 185/60/R15 | E10: ALNAC 4G | F10: 4 | G10: 42 | H10: 168
A11: MICHELIN | B11: MICHELIN 235/50/R18 PRIMACY 5 97W | C11: 235/50/R18 | D11: 235/50/R18 | E11: PRIMACY 5 | F11: 4 | G11: 12 | H11: 48
A12: ARIVO | B12: ARIVO 185/60/R15 PREMIO ARZ1 88H | C12: 185/60/R15 | D12: 185/60/R15 | E12: PREMIO ARZ1 | F12: 4 | G12: 50 | H12: 200
A13: ARIVO | B13: ARIVO 175/65/R14 PREMIO ARZ1 82H | C13: 175/65/R14 | D13: 175/65/R14 | E13: PREMIO ARZ1 | F13: 4 | G13: 61 | H13: 244
... A1615: FRONWAY | B1615: FRONWAY 165/65/R14 ECOGREEN ONE 79T | C1615: 165/65/R14 | D1615: 165/65/R14 | E1615: ECOGREEN ONE | F1615: 1 | G1615: 1 | H1615: 1

Sheet 2026 - Raw Data
A1: Brand | B1: SKU | C1: Original Size | D1: Final Size (used) | E1: Pattern (extracted) | F1: Pack Qty | G1: Orders | H1: Count (tires)
A2: MICHELIN | B2: MICHELIN 265/65/R17 PRIMACY SUV+ 112H | C2: 265/65/R17 | D2: 265/65/R17 | E2: PRIMACY SUV+ | F2: 4 | G2: 21 | H2: 84
A3: MICHELIN | B3: MICHELIN 265/60/R18 PRIMACY SUV+ 110H | C3: 265/60/R18 | D3: 265/60/R18 | E3: PRIMACY SUV+ | F3: 4 | G3: 17 | H3: 68
A4: MICHELIN | B4: MICHELIN 235/50/R19 PRIMACY 5 103W | C4: 235/50/R19 | D4: 235/50/R19 | E4: PRIMACY 5 | F4: 4 | G4: 13 | H4: 52
A5: MICHELIN | B5: MICHELIN 185/60/R15 ENERGY XM2+ 88H | C5: 185/60/R15 | D5: 185/60/R15 | E5: ENERGY XM2+ | F5: 4 | G5: 29 | H5: 116
A6: BFGOODRICH | B6: BFGOODRICH 225/55/R18 ADVANTAGE TOURING 98H | C6: 225/55/R18 | D6: 225/55/R18 | E6: ADVANTAGE TOURING | F6: 4 | G6: 23 | H6: 92
A7: BRIDGESTONE | B7: BRIDGESTONE 265/60/R18 DUELER H/T 684 (RBT) 110H | C7: 265/60/R18 | D7: 265/60/R18 | E7: DUELER H/T 684 (RBT) | F7: 4 | G7: 13 | H7: 52
A8: MICHELIN | B8: MICHELIN 235/60/R18 E PRIMACY ST 103H | C8: 235/60/R18 | D8: 235/60/R18 | E8: E PRIMACY ST | F8: 4 | G8: 13 | H8: 52
A9: MICHELIN | B9: MICHELIN 235/50/R18 PRIMACY 5 97W | C9: 235/50/R18 | D9: 235/50/R18 | E9: PRIMACY 5 | F9: 4 | G9: 13 | H9: 52
A10: MICHELIN | B10: MICHELIN 225/65/R17 PRIMACY SUV+ 106H | C10: 225/65/R17 | D10: 225/65/R17 | E10: PRIMACY SUV+ | F10: 4 | G10: 15 | H10: 60
A11: MICHELIN | B11: MICHELIN 225/55/R19 PRIMACY SUV+ 99V | C11: 225/55/R19 | D11: 225/55/R19 | E11: PRIMACY SUV+ | F11: 4 | G11: 13 | H11: 52
A12: MICHELIN | B12: MICHELIN 265/50/R20 PILOT SPORT 4 SUV 107V | C12: 265/50/R20 | D12: 265/50/R20 | E12: PILOT SPORT 4 SUV | F12: 4 | G12: 12 | H12: 48
A13: MICHELIN | B13: MICHELIN 235/50/R19 PILOT SPORT 4 SUV S1 99V | C13: 235/50/R19 | D13: 235/50/R19 | E13: PILOT SPORT 4 SUV S1 | F13: 4 | G13: 8 | H13: 32
... A21: MICHELIN | B21: MICHELIN 215/60/R17 PRIMACY 5 100V | C21: 215/60/R17 | D21: 215/60/R17 | E21: PRIMACY 5 | F21: 4 | G21: 12 | H21: 48
A22: MICHELIN | B22: MICHELIN 255/40/ZR19 PILOT SPORT 5 100Y | D22: 255/40/R19 | E22: PILOT SPORT 5 | F22: 4 | G22: 8 | H22: 32
A23: MICHELIN | B23: MICHELIN 235/40/ZR18 PILOT SPORT 5 95Y XL TL | D23: 235/40/R18 | E23: PILOT SPORT 5 | F23: 4 | G23: 9 | H23: 36
A24: MICHELIN | B24: MICHELIN 235/60/R18 PRIMACY SUV+ 103V | C24: 235/60/R18 | D24: 235/60/R18 | E24: PRIMACY SUV+ | F24: 4 | G24: 9 | H24: 36
A25: MICHELIN | B25: MICHELIN 225/60/R17 PRIMACY 5 103V | C25: 225/60/R17 | D25: 225/60/R17 | E25: PRIMACY 5 | F25: 4 | G25: 9 | H25: 36
A26: MICHELIN | B26: MICHELIN 185/55/R15 ENERGY XM2+ 86V | C26: 185/55/R15 | D26: 185/55/R15 | E26: ENERGY XM2+ | F26: 4 | G26: 17 | H26: 68
A27: DUNLOP | B27: DUNLOP 215/60/R17 ENASAVE EC300+ 96H | C27: 215/60/R17 | D27: 215/60/R17 | E27: ENASAVE EC300+ | F27: 4 | G27: 12 | H27: 48
A28: MICHELIN | B28: MICHELIN 245/40/ZR18 PILOT SPORT 5 97Y XL TL | D28: 245/40/R18 | E28: PILOT SPORT 5 | F28: 4 | G28: 8 | H28: 32
A29: MICHELIN | B29: MICHELIN 195/60/R16 PRIMACY 5 93V | C29: 195/60/R16 | D29: 195/60/R16 | E29: PRIMACY 5 | F29: 4 | G29: 12 | H29: 48
A30: MICHELIN | B30: MICHELIN 215/55/R17 PRIMACY 5 94V | C30: 215/55/R17 | D30: 215/55/R17 | E30: PRIMACY 5 | F30: 4 | G30: 10 | H30: 40
A31: MICHELIN | B31: MICHELIN 185/55/R16 ENERGY XM2+ 83V | C31: 185/55/R16 | D31: 185/55/R16 | E31: ENERGY XM2+ | F31: 4 | G31: 14 | H31: 56
A32: BRIDGESTONE | B32: BRIDGESTONE 185/65/R15 ECOPIA EP300 88H | C32: 185/65/R15 | D32: 185/65/R15 | E32: ECOPIA EP300 | F32: 4 | G32: 19 | H32: 76
A33: MICHELIN | B33: MICHELIN 205/55/R16 ENERGY XM2+ 91V | C33: 205/55/R16 | D33: 205/55/R16 | E33: ENERGY XM2+ | F33: 4 | G33: 13 | H33: 52
A34: BRIDGESTONE | B34: BRIDGESTONE 215/55/R17 TURANZA ER33 94V | C34: 215/55/R17 | D34: 215/55/R17 | E34: TURANZA ER33 | F34: 4 | G34: 13 | H34: 52
A35: MICHELIN | B35: MICHELIN 175/65/R15 ENERGY XM2+ 84H | C35: 175/65/R15 | D35: 175/65/R15 | E35: ENERGY XM2+ | F35: 4 | G35: 16 | H35: 64
A36: YOKOHAMA | B36: YOKOHAMA 185/60/R15 BLUEARTH ES32 84H | C36: 185/60/R15 | D36: 185/60/R15 | E36: BLUEARTH ES32 | F36: 4 | G36: 16 | H36: 64
A37: BRIDGESTONE | B37: BRIDGESTONE 195/60/R16 ECOPIA EP150 89H | C37: 195/60/R16 | D37: 195/60/R16 | E37: ECOPIA EP150 | F37: 4 | G37: 12 | H37: 48
A38: BFGOODRICH | B38: BFGOODRICH 235/55/R18 ADVANTAGE TOURING 104H | C38: 235/55/R18 | D38: 235/55/R18 | E38: ADVANTAGE TOURING | F38: 4 | G38: 11 | H38: 44
A39: MICHELIN | B39: MICHELIN 225/50/R18 PRIMACY 5 99W | C39: 225/50/R18 | D39: 225/50/R18 | E39: PRIMACY 5 | F39: 4 | G39: 7 | H39: 28
A40: MICHELIN | B40: MICHELIN 225/45/R17 PRIMACY 5 94W XL | C40: 225/45/R17 | D40: 225/45/R17 | E40: PRIMACY 5 | F40: 4 | G40: 8 | H40: 32
... A54: ARIVO | B54: ARIVO 185/60/R15 PREMIO COMFORT 6 88H | C54: 185/60/R15 | D54: 185/60/R15 | E54: PREMIO COMFORT 6 | F54: 4 | G54: 21 | H54: 84
A55: MICHELIN | B55: MICHELIN 245/40/ZR19 PILOT SPORT 5 98Y | D55: 245/40/R19 | E55: PILOT SPORT 5 | F55: 4 | G55: 4 | H55: 16
A56: MICHELIN | B56: MICHELIN 265/70/R16 LTX TRAIL 112T | C56: 265/70/R16 | D56: 265/70/R16 | E56: LTX TRAIL | F56: 24 | G56: 1 | H56: 24
A57: MICHELIN | B57: MICHELIN 255/45/ZR19 PILOT SPORT 5 104Y XL TL | D57: 255/45/R19 | E57: PILOT SPORT 5 | F57: 4 | G57: 4 | H57: 16
A58: MICHELIN | B58: MICHELIN 245/35/ZR20 PILOT SPORT 4S 95Y XL TL | D58: 245/35/R20 | E58: PILOT SPORT 4S | F58: 8 | G58: 1 | H58: 8
A59: MICHELIN | B59: MICHELIN 265/60/R18 LTX TRAIL 110T | C59: 265/60/R18 | D59: 265/60/R18 | E59: LTX TRAIL | F59: 4 | G59: 4 | H59: 16
A60: ARIVO | B60: ARIVO 185/55/R15 PREMIO COMFORT 6 | C60: 185/55/R15 | D60: 185/55/R15 | E60: PREMIO COMFORT 6 | F60: 4 | G60: 20 | H60: 80
...
